Workbook
Name sspdtipos_TipoIdentificacion: Lists!$B$3:$B$5
Name sspdtipos_TipoGrupoMarcoNormativo: Lists!$D$3:$D$5
Name sspdtipos_TipoDeclaracionCumplimientoMarcoNormativo: Lists!$F$3:$F$4
Name sspdtipos_TipoSiNo: Lists!$H$3:$H$4

Sheet Indice
B2: Tabla de contenidos
B3: [110000t] Información a revelar sobre la Entidad Informante
B4: [120000t] Información adicional a revelar
B5: [210000t] Estado de situación financiera
B6: [310000t] Estado de resultados
B7: [900020t] FC03t - Cuentas comerciales por cobrar y otras cuentas por cobrar
B8: [900028t] FC05t - Cuentas comerciales por pagar, otras cuentas por pagar y otros pasivos
B9: [900050t] FC08t - Información de ingresos y gastos de la entidad
B10: [900060t] FC09t - Deterioro de activos

Sheet Hoja1
B2: Indice
B3: Archivo: | C3: C:\Users\rekin\OneDrive\1. Documentos 2025\Empocruz ESP\Taxonomías\Taxo202502\IFE_SegundoTrimestre_ID20037_2025-06-30.xbrl
B4: Empresa: | C4: 20037
B5: Vista: | C5: [110000t] Información a revelar sobre la Entidad Informante
B6: Eje X: | C6: N/A
B7: Eje Y: | C7: N/A
B8: Eje Z: | C8: N/A
E10: Periodo Actual
B11: Información a revelar sobre la Entidad Informante [Abstracto]
C12: Datos Básicos [Abstracto]
D13: NIT | E13: 814005646
D14: Identificación de la Empresa (ID RUPS) | E14: 20037
D15: Nombre de la entidad que informa u otras formas de identificación | E15: EMPRESA DE SERVICIOS PUBLICOS DE LA CRUZ - EMPOCRUZ E.S.P
D16: Fecha de cierre del periodo sobre el que se informa | E16: 2025-06-30
C17: Datos de Ubicación [Abstracto]
D18: Dirección de la sede administrativa de la entidad | E18: Calle 6 Nro. 8-02
D19: Ciudad donde se encuentra ubicada la sede administrativa | E19: LA-CRUZ-NARINO
D20: Número de teléfono fijo de la sede administrativa | E20: 3116151373
D21: Número de teléfono celular de la sede administrativa | E21: 3116151373
D22: Email Corporativo | E22: gerencia@empocruz.gov.co
C23: Información sobre empleados [Abstracto]
D24: Numero de empleados y contratistas al comienzo del periodo | E24: 35
D25: Numero de empleados y contratistas al final del periodo | E25: 35
D26: Numero promedio de empleados y contratistas | E26: 35
C27: Representación legal [Abstracto]
D28: Tipo de documento | E28: 01 - CÉDULA DE CIUDADANÍA
D29: Número de documento | E29: 87249156
D30: Nombres | E30: JONATHAN ALEXANDER
D31: Apellidos | E31: BOLAÑOS MUÑOZ
C32: Marco normativo [Abstracto]
D33: Grupo en que se encuentra clasificada la Entidad | E33: R. 414
D34: Declaración de cumplimiento del marco normativo | E34: 1. Si cumple
D35: Información a revelar sobre incertidumbres sobre la capacidad de la entidad para continuar como negocio en marcha | E35: NA
D36: Explicación de la razón por la que no se considera a la entidad como negocio en marcha | E36: NA
C37: Información a revelar sobre finalización de la prestación de los servicios inscritos en RUPS [Abstracto]
D38: Información a revelar sobre incertidumbres sobre la capacidad de dar continuidad a la prestación de uno o más servicios inscritos en RUPS | E38: NA
D39: ¿Durante el periodo sobre el que se informa se finalizó la prestación de uno o más servicios inscritos en RUPS? | E39: 2. No
D40: Detalle sobre la finalización de la prestación de los servicios inscritos en RUPS. (indicar servicio y fecha de finalización del servicio, indicar si otra empresa tomó la prestación, ¿cuál?)

Sheet Lists
B3: 01 - CÉDULA DE CIUDADANÍA | D3: Grupo 1 | F3: 1. Si cumple | H3: 1. Si
B4: 02 - CÉDULA DE EXTRANJERÍA | D4: Grupo 2 | F4: 2. No cumple | H4: 2. No
B5: 03 - PASAPORTE | D5: R. 414

Sheet Hoja2
B2: Indice
B3: Archivo: | C3: C:\Users\rekin\OneDrive\1. Documentos 2025\Empocruz ESP\Taxonomías\Taxo202502\IFE_SegundoTrimestre_ID20037_2025-06-30.xbrl
B4: Empresa: | C4: 20037
B5: Vista: | C5: [120000t] Información adicional a revelar
B6: Eje X: | C6: N/A
B7: Eje Y: | C7: N/A
B8: Eje Z: | C8: N/A
G10: Periodo Actual
B11: Información adicional a revelar [Abstracto]
C12: Variaciones en el flujo de efectivo [Abstracto]
D13: Efectivo y equivalentes al efectivo al comienzo del periodo | G13: 97671293
E14: Información a revelar variaciones de flujo de efectivo | G14: ND
D15: Incrementos (disminuciones) | G15: 14097404
D16: Efectivo y equivalentes al efectivo al final del periodo | G16: 111768697
C17: Otra información a revelar [Abstracto]
D18: Información relevante a revelar sobre el periodo cubierto por este informe | G18: ND
D19: Información a revelar sobre los activos | G19: ND
D20: Información a revelar sobre los pasivos | G20: ND
D21: Información a revelar sobre el patrimonio | G21: ND
D22: Información a revelar sobre ingresos | G22: ND
D23: Información a revelar sobre gastos | G23: ND
C24: Información a revelar en relación con modificaciones a trimestres anteriores [Abstracto]
D25: ¿Ha habido ajustes a información certificada en SUI de trimestres anteriores? | G25: 2. No
E26: ¿Los ajustes corresponden a cuarto trimestre del año anterior?
F27: Explique los ajustes efectuados a la información certificada en el cuarto trimestre
E28: ¿Los ajustes corresponden a primer trimestre de este año?
F29: Explique los ajustes efectuados a la información certificada en el primer trimestre
E30: ¿Los ajustes corresponden a segundo trimestre de este año?
F31: Explique los ajustes efectuados a la información certificada en el segundo trimestre
E32: ¿Los ajustes corresponden a tercer trimestre de este año?
F33: Explique los ajustes efectuados a la información certificada en el tercer trimestre

Sheet Hoja3
B2: Indice
B3: Archivo: | C3: C:\Users\rekin\OneDrive\1. Documentos 2025\Empocruz ESP\Taxonomías\Taxo202502\IFE_SegundoTrimestre_ID20037_2025-06-30.xbrl
B4: Empresa: | C4: 20037
B5: Vista: | C5: [210000t] Estado de situación financiera
B6: Eje X: | C6: N/A
B7: Eje Y: | C7: N/A
B9: Eje Z: | C9: Periodo Actual
I10: Total por servicios [miembro]
I11: Acueducto [miembro] | J11: Alcantarillado [miembro] | K11: Aseo [miembro] | L11: Energía Eléctrica [miembro] | M11: Gas combustible por redes [miembro] | N11: Gas Licuado de Petróleo [miembro] | O11: Operador del sistema y Administrador del mercado de energia (XM) [miembro] | P11: Otras actividades no vigiladas por la SSPD [miembro]
B12: Estado de situación financiera por servicio [partidas]
C13: Activos [resumen]
D14: Activos corrientes [resumen]
E15: Efectivo y equivalentes al efectivo | I15: 32439054 | J15: 26996806 | K15: 52332837 | Q15: =Hoja2!G16
F16: Efectivo y equivalente al efectivo de uso restringido corrientes
E17: Cuentas comerciales por cobrar y otras cuentas por cobrar corrientes [Resumen]
F18: Cuentas comerciales por cobrar por prestación de servicios públicos corrientes [Resumen]
G19: Cuentas comerciales por cobrar corrientes por prestación de servicios públicos corrientes (Sin incluir subsidios ni actividades de aprovechamiento) | I19: 19322948 | J19: 9102524 | K19: 12982174 | Q19: 41407646
G20: Cuentas comerciales por cobrar por subsidios corrientes | I20: 24469246 | J20: 13141929 | K20: 15333256 | Q20: 52944431
H21: Cuentas comerciales por cobrar corrientes del servicio público al Ministerio de Minas por concepto de subsidios
G22: Cuentas comerciales por cobrar por actividad de aprovechamiento corrientes
F23: Total cuentas comerciales por cobrar por prestación de servicios públicos corrientes | I23: 0 | J23: 0 | K23: 0 | L23: 0 | M23: 0 | N23: =N19+N20 | P23: =P19+P20 | Q23: =Q19+Q20+Q22
F24: Cuentas comerciales por cobrar por venta de bienes corrientes | I24: 118030 | Q24: =-Hoja5!L28+Hoja5!L27
F25: Otras cuentas por cobrar corrientes | I25: 10011109 | Q25: =Hoja5!L31-Hoja5!L32
F26: Total cuentas comerciales por cobrar y otras cuentas por cobrar corrientes | I26: 0 | J26: 0 | K26: 0 | L26: 0 | M26: 0 | N26: =SUM(N23:N25) | O26: =SUM(O23:O25) | P26: =SUM(P23:P25) | Q26: =SUM(Q23:Q25)
E27: Inventarios corrientes | I27: 15974333 | Q27: 15974333
E28: Inversiones corrientes
E29: Anticipo de impuestos
E30: Otros activos financieros corrientes
E31: Otros activos no financieros corrientes
E32: Activos corrientes totales | I32: 0 | J32: 0 | K32: 0 | L32: 0 | M32: 0 | N32: =N15+SUM(N26:N31) | O32: =O15+SUM(O26:O31) | P32: =P15+SUM(P26:P31) | Q32: =Q15+SUM(Q26:Q31)
D33: Activos no corrientes [resumen]
E34: Propiedades, planta y equipo | I34: 718819563 | J34: 4882168 | K34: 10966643 | Q34: 734668374
E35: Propiedades de inversión
E36: Activos intangibles distintos a la plusvalía | I36: 15380134 | Q36: 15380134
E37: Inversiones no corrientes
E38: Cuentas comerciales por cobrar y otras cuentas por cobrar no corrientes [Resumen]
F39: Cuentas comerciales por cobrar por prestación de servicios públicos no corrientes [Resumen]
G40: Cuentas comerciales por cobrar no corrientes por prestación de servicios públicos corrientes (Sin incluir subsidios ni actividades de aprovechamiento)
G41: Cuentas comerciales por cobrar por subsidios no corrientes
H42: Cuentas comerciales por cobrar no corrientes del servicio público al Ministerio de Minas por concepto de subsidios
...

Sheet Hoja4
B2: Indice
B3: Archivo: | C3: C:\Users\rekin\OneDrive\1. Documentos 2025\Empocruz ESP\Taxonomías\Taxo202502\IFE_SegundoTrimestre_ID20037_2025-06-30.xbrl
B4: Empresa: | C4: 20037
B5: Vista: | C5: [310000t] Estado de resultados
B6: Eje X: | C6: N/A
B7: Eje Y: | C7: N/A
B9: Eje Z: | C9: Periodo Actual
E10: Total por servicios [miembro]
E11: Acueducto [miembro] | F11: Alcantarillado [miembro] | G11: Aseo [miembro] | H11: Energía Eléctrica [miembro] | I11: Gas combustible por redes [miembro] | J11: Gas Licuado de Petróleo [miembro] | K11: Operador del sistema y Administrador del mercado de energia (XM) [miembro] | L11: Otras actividades no vigiladas por la SSPD [miembro]
B12: Estado de resultados por servicio [partidas]
C13: Ganancia (pérdida) [resumen]
D14: Ingresos de actividades ordinarias | E14: 549440143 | F14: 180509891 | G14: 261207690 | M14: 991157724
D15: Costo de ventas | E15: 356426319 | F15: 180483023 | G15: 196249412 | M15: 733158754
D16: Ganancia bruta | E16: =E14-E15 | F16: 0 | G16: 0 | H16: 0 | I16: 0 | J16: 0 | K16: 0 | L16: 0 | M16: 0
D17: Gastos de administración, operación y ventas | E17: 144077842 | F17: 101584033 | G17: 17202774 | M17: 262864649
D18: Otros ingresos | E18: 346590 | F18: 150000000 | M18: 150346590
D19: Otros gastos | E19: 35659238 | F19: 6600000 | G19: 1760000 | M19: 44019238
D20: Ganancia (pérdida) por actividades de operación | E20: =E16-E17-E19+E18 | F20: 0 | G20: 0 | H20: 0 | I20: 0 | J20: 0 | K20: 0 | L20: 0 | M20: 0
D21: Ingresos financieros | E21: 22237136 | M21: 22237136
D22: Costos financieros | E22: 5913857 | F22: 2861955 | G22: 763188 | M22: 9539000
D23: Otras ganancias (pérdidas)
D24: Ganancia (pérdida), antes de impuestos | E24: =E20+E21-E22+E23 | F24: 0 | G24: 0 | H24: 0 | I24: 0 | J24: 0 | K24: 0 | L24: 0 | M24: 0
D25: Gasto (ingreso) por impuesto de operaciones continuadas
D26: Ganancia (pérdida) procedente de operaciones continuadas | E26: =E24-E25 | F26: 0 | G26: 0 | H26: 0 | I26: 0 | J26: 0 | K26: 0 | L26: 0 | M26: 0
D27: Ganancia (pérdida) procedente de operaciones discontinuadas
D28: Ganancia (pérdida) | E28: =E26+E27 | F28: 0 | G28: 0 | H28: 0 | I28: 0 | J28: 0 | K28: 0 | L28: 0 | M28: 0
B30: Eje Z: | C30: Periodo Comparado
E31: Total por servicios [miembro]
E32: Acueducto [miembro] | F32: Alcantarillado [miembro] | G32: Aseo [miembro] | H32: Energía Eléctrica [miembro] | I32: Gas combustible por redes [miembro] | J32: Gas Licuado de Petróleo [miembro] | K32: Operador del sistema y Administrador del mercado de energia (XM) [miembro] | L32: Otras actividades no vigiladas por la SSPD [miembro]
B33: Estado de resultados por servicio [partidas]
C34: Ganancia (pérdida) [resumen]
D35: Ingresos de actividades ordinarias | E35: 288598804 | F35: 64899827 | G35: 112430345 | M35: 465928976
D36: Costo de ventas | E36: 180846963 | F36: 74147725 | G36: 97234060 | M36: 352228748
D37: Ganancia bruta | E37: =E35-E36 | F37: 0 | G37: 0 | H37: 0 | I37: 0 | J37: 0 | K37: 0 | L37: 0 | M37: 0
D38: Gastos de administración, operación y ventas | E38: 50494231 | F38: 24432692 | G38: 6515385 | M38: 81442308
D39: Otros ingresos | E39: 7013179 | F39: 75000000 | M39: 82013179
D40: Otros gastos | E40: 61411341 | F40: 16220930 | G40: 4141368 | M40: 81773639
D41: Ganancia (pérdida) por actividades de operación | E41: =E37-E38-E40+E39 | F41: 0 | G41: 0 | H41: 0 | I41: 0 | J41: 0 | K41: 0 | L41: 0 | M41: 0
D42: Ingresos financieros
D43: Costos financieros
...

Sheet Hoja5
B2: Indice
B3: Archivo: | C3: C:\Users\rekin\OneDrive\1. Documentos 2025\Empocruz ESP\Taxonomías\Taxo202502\IFE_SegundoTrimestre_ID20037_2025-06-30.xbrl
B4: Empresa: | C4: 20037
B5: Vista: | C5: [900020t] FC03t - Cuentas comerciales por cobrar y otras cuentas por cobrar
B6: Eje X: | C6: N/A
B7: Eje Y: | C7: N/A
B8: Eje Z: | C8: Periodo Actual
F10: Valor cuentas comerciales por cobrar y otras cuentas por cobrar [miembro]
F11: Total [miembro]
F12: No vencidas [miembro] | G12: Vencidas [miembro]
G13: Vencidas de 1 a 90 días [miembro] | H13: Vencidas de 91 a 180 días [miembro] | I13: Vencidas de 181 a 360 días [miembro] | J13: Vencidas de mas de 360 días [miembro]
B14: Detalle de cuentas comerciales por cobrar y otras cuentas por cobrar por prestación de servicios públicos [abstracto]
C15: Cuentas comerciales por cobrar corrientes por prestación de servicios públicos y otras cuentas por cobrar corrientes [abstracto]
D16: Cuentas comerciales por cobrar corrientes por prestación de servicios públicos [abstracto]
E17: Acueducto | H17: 43792194 | K17: 43792194 | L17: 43792194
E18: Alcantarillado | H18: 22244453 | K18: 22244453 | L18: 22244453
E19: Aseo | H19: 28315430 | K19: 28315430 | L19: 28315430
E20: Energía
E21: Gas Combustible por redes
E22: Gas Licuado de Petróleo
E23: Operador del sistema y administrador del mercado de energia (XM)
E24: Deterioro de cuentas comerciales por cobrar corrientes por prestación de servicios públicos
E25: Total cuentas comerciales por cobrar corrientes netas por prestación de servicios públicos | F25: 0 | G25: 0 | H25: 0 | I25: 0 | J25: 0 | K25: 0 | L25: 0
D26: Cuentas comerciales por cobrar corrientes por venta de bienes [abstracto]
E27: Cuentas comerciales por cobrar corrientes brutas por venta de bienes | H27: 118030 | K27: 118030 | L27: 118030
E28: Deterioro de cuentas por cobrar corrientes por venta de bienes
E29: Total cuentas comerciales por cobrar corrientes netas por venta de bienes | F29: 0 | G29: 0 | H29: 0 | I29: 0 | J29: 0 | K29: 0 | L29: 0
D30: Otras cuentas comerciales por cobrar corrientes [abstracto]
E31: Otras cuentas comerciales por cobrar corrientes brutas | H31: 10011109 | K31: 10011109 | L31: 10011109
E32: Deterioro de otras cuentas por cobrar corrientes
E33: Total otras cuentas comerciales por cobrar corrientes netas | F33: 0 | G33: 0 | H33: 0 | I33: 0 | J33: 0 | K33: 0 | L33: 0
D34: Total cuentas comerciales por cobrar corrientes netas por prestación de servicios públicos y otras cuentas comerciales por cobrar corrientes netas | F34: 0 | G34: 0 | H34: 0 | I34: 0 | J34: 0 | K34: 0 | L34: 0
C35: Cuentas comerciales por cobrar no corrientes por prestación de servicios públicos y otras cuentas por cobrar no corrientes [abstracto]
D36: Cuentas comerciales por cobrar no corrientes por prestación de servicios públicos [abstracto]
E37: Acueducto
E38: Alcantarillado
E39: Aseo
E40: Energía
E41: Gas Combustible por redes
E42: Gas Licuado de Petróleo
...

Sheet Hoja6
B2: Indice
B3: Archivo: | C3: C:\Users\rekin\OneDrive\1. Documentos 2025\Empocruz ESP\Taxonomías\Taxo202502\IFE_SegundoTrimestre_ID20037_2025-06-30.xbrl
B4: Empresa: | C4: 20037
B5: Vista: | C5: [900028t] FC05t - Cuentas comerciales por pagar, otras cuentas por pagar y otros pasivos
B6: Eje X: | C6: N/A
B7: Eje Y: | C7: N/A
B8: Eje Z: | C8: Periodo Actual
D10: Valor cuentas comerciales por pagar y otros pasivos financieros [miembro]
D11: Total [miembro]
D12: No vencidas [miembro] | E12: Vencidas [miembro]
E13: Vencidas de 1 a 90 días [miembro] | F13: Vencidas de 91 a 180 días [miembro] | G13: Vencidas de 181 a 360 días [miembro] | H13: Vencidas de mas de 360 días [miembro]
B14: Detalle de cuentas comerciales por pagar, otras cuentas por pagar y otros pasivos financieros [abstracto]
C15: Cuentas comerciales por pagar | D15: 35214477 | J15: 35214477
C16: Otras cuentas por pagar
C17: Total cuentas comerciales por pagar y otras cuentas por pagar | D17: =D15+D16 | E17: =E15+E16 | F17: 0 | G17: 0 | H17: 0 | I17: 0 | J17: 0
C18: Obligaciones financieras
C19: Obligaciones laborales | D19: 14788927 | J19: 14788927
C20: Total cuentas comerciales por pagar, otras cuentas por pagar y otros pasivos financieros | D20: =SUM(D17:D19) | E20: =SUM(E17:E19) | F20: 0 | G20: 0 | H20: 0 | I20: 0 | J20: 0

Sheet Hoja7
B2: Indice
B3: Archivo: | C3: C:\Users\rekin\OneDrive\1. Documentos 2025\Empocruz ESP\Taxonomías\Taxo202502\IFE_SegundoTrimestre_ID20037_2025-06-30.xbrl
B4: Empresa: | C4: 20037
B5: Vista: | C5: [900050t] FC08t - Información de ingresos y gastos de la entidad
B6: Eje X: | C6: N/A
B7: Eje Y: | C7: N/A
B8: Eje Z: | C8: Periodo Actual
F10: Total por servicios [miembro]
F11: Acueducto [miembro] | G11: Alcantarillado [miembro] | H11: Aseo [miembro] | I11: Energía Eléctrica [miembro] | J11: Gas combustible por redes [miembro] | K11: Gas Licuado de Petróleo [miembro] | L11: Operador del sistema y Administrador del mercado de energia (XM) [miembro] | M11: Otras actividades no vigiladas por la SSPD [miembro]
B12: Detalle de ingresos y gastos del periodo [abstracto]
C13: Detalle de ingresos [abstracto]
D14: Ingresos de actividades ordinarias | F14: 549440143 | G14: 180509891 | H14: 261207690 | N14: =Hoja4!M14
D15: Todos los demás ingresos | F15: 22583726 | G15: 150000000 | N15: 172583726
D16: Total ingresos | F16: 0 | G16: 0 | H16: 0 | I16: 0 | J16: 0 | K16: 0 | L16: 0 | M16: 0 | N16: =N14+N15
C17: Detalle de gastos [abstracto]
D18: Costos y gastos totales | F18: 542077256 | G18: 291529011 | H18: 215975374 | N18: 1049581641
E19: Impuestos, tasas y contribuciones | F19: 0 | G19: 0 | H19: 0 | N19: 0
E20: Gastos financieros | F20: 5913857 | G20: 2861955 | H20: 763188 | N20: 9539000
E21: Gasto por deterioro | F21: 0 | G21: 0 | H21: 0 | N21: 0
E22: Gasto por depreciación | F22: 0 | G22: 0 | H22: 0 | N22: 0
E23: Gasto por amortización | F23: 0 | G23: 0 | H23: 0 | N23: 0
E24: Gasto por provisiones | F24: 0 | G24: 0 | H24: 0 | N24: 0

Sheet Hoja8
B2: Indice
B3: Archivo: | C3: C:\Users\rekin\OneDrive\1. Documentos 2025\Empocruz ESP\Taxonomías\Taxo202502\IFE_SegundoTrimestre_ID20037_2025-06-30.xbrl
B4: Empresa: | C4: 20037
B5: Vista: | C5: [900060t] FC09t - Deterioro de activos
B6: Eje X: | C6: N/A
B7: Eje Y: | C7: N/A
B8: Eje Z: | C8: Periodo Actual
D10: Deterioro de activos [miembro]
D11: Activos intangibles distintos de la plusvalía [miembro] | E11: Cuentas comerciales por cobrar [miembro] | F11: Inversiones [miembro] | G11: Propiedades, planta y equipo [miembro] | H11: Inventarios [miembro] | I11: Otros activos [miembro]
B12: Información a revelar sobre pérdidas por deterioro [abstracto]
C13: Pérdidas por deterioro de valor reconocidas en el resultado del periodo
C14: Reversión de pérdidas por deterioro de valor reconocidas en el resultado del periodo
C15: Total pérdidas por deterioro de valor | D15: =-D14+D13 | E15: =-E14+E13 | F15: 0 | G15: 0 | H15: 0 | I15: 0 | J15: 0
