Workbook
Name sspdtipos_TipoGradoRedondeo: Lists!$B$3:$B$6
Name sspdtipos_TipoSiNo: Lists!$D$3:$D$4
Name sspdtipos_TipoPeriodoDeReexpresion: Lists!$F$3:$F$5
Name sspdtipos_TipoDivisa: Lists!$H$3:$H$5
Name sspdtipos_TipoIdentificacionResponsablesInformacion: Lists!$J$3:$J$5
Name sspdtipos_TipoDeDictamenDeAuditoria: Lists!$L$3:$L$10
Name sspdtipos_TipoClasificacionEmpresarialSegunResolucionCRA906Del2019: Lists!$N$3:$N$6
Name sspdtipos_TipoPeriodoFaseDeProgresividad: Lists!$P$3:$P$15

Sheet Indice
B2: Tabla de contenidos
B3: [110000] Información general sobre estados financieros
B4: [210000] Estado de situación financiera (corriente/no corriente) - Individual
B5: [310000] Estado de Resultados Integral, resultado del periodo, por función del gasto - Individual
B6: [420000] Estado de Resultados Integral, componentes ORI presentados antes de impuestos - Individual
B7: [510000] Estado de flujos de efectivo, método directo - Individual
B8: [610000] Estado de cambios en el patrimonio - Individual
B9: [800100] Notas - Subclasificaciones de activos, pasivos y patrimonios
B10: [800500] Notas - Lista de Notas
B11: [800600] Notas - Lista de políticas contables
B12: [810000] Notas - Información de la entidad y declaración de cumplimiento con el marco normativo
B13: [811001] Notas - Cambios por políticas contables, estimaciones contables o corrección de errores
... B66: [900110] FC60 - Porcentaje de provisión de la tarifa de aprovechamiento

Sheet Hoja1
B2: Indice
B3: Archivo: | C3: I:\Proyectos2025\proyecto_niif\_backup_legacy\Grupo1_Individual_Directo_ID20037_2024-12-31.xbrl
B4: Empresa: | C4: 20037
B5: Vista: | C5: [110000] Información general sobre estados financieros
B6: Eje X: | C6: N/A
B7: Eje Y: | C7: N/A
B8: Eje Z: | C8: N/A
E10: Periodo Actual
B11: Información general [resumen]
C12: Información a revelar sobre información general sobre los estados financieros [bloque de texto]
D13: Nombre de la entidad que informa u otras formas de identificación
D14: Identificación de la Empresa (ID RUPS)
D15: NIT
D16: Información a revelar sobre la naturaleza del negocio
D17: Fecha de inicio de operaciones (o fecha de constitución si no ha iniciado la prestación de servicios)
D18: Fecha de cierre del periodo sobre el que se informa
D19: Grado de redondeo utilizado en los estados financieros
C20: Detalle sobre este Informe
D21: ¿Estos estados financieros presentan información reexpresada?
D22: Periodo para el cual se presenta información reexpresada

Sheet Lists
B3: 1 - Pesos | D3: 1. Si | F3: 1. Reexpresión del patrimonio al inicio del periodo actual (Del patrimonio del periodo anterior) | H3: COP - Colombian peso | J3: 01 - CÉDULA DE CIUDADANÍA | L3: NAGAS - 1. Limpio | N3: 1 - Grandes Prestadores | P3: 2018
B4: 2 - Miles de pesos | D4: 2. No | F4: 2. Reexpresión del patrimonio al inicio del periodo anterior (Del patrimonio de dos periodos atrás) | H4: EUR - Euro | J4: 02 - CÉDULA DE EXTRANJERÍA | L4: NAGAS - 2. Con salvedad | N4: 2 - Pequeños Prestadores | P4: 2019
B5: 3 - Millones de pesos | F5: 3. Reexpresión del patrimonio al inicio de los periodos actual y anterior (Del patrimonio del periodo anterior y de dos periodos atrás) | H5: USD - US Dollar | J5: 03 - PASAPORTE | L5: NAGAS - 3. Negativo | N5: 3 - Prestadores Rurales | P5: 2020
B6: 4 - Pesos redondeada a miles | L6: NAGAS - 4. Abstención de opinión | N6: 4 - Esquema Diferencial | P6: 2021
L7: NIAS - 1. No modificada | P7: 2022
L8: NIAS - 2. Modificada; opinión con salvedades | P8: 2023
L9: NIAS - 3. Modificada; opinión desfavorable o adversa | P9: 2024
L10: NIAS - 4. Modificada; denegación o abstención de opinión | P10: 2025
P11: 2026
P12: 2027
P13: 2028
P14: 2029
P15: 2030

Sheet Hoja2
B2: Indice
B3: Archivo: | C3: I:\Proyectos2025\proyecto_niif\_backup_legacy\Grupo1_Individual_Directo_ID20037_2024-12-31.xbrl
B4: Empresa: | C4: 20037
B5: Vista: | C5: [210000] Estado de situación financiera (corriente/no corriente) - Individual
B6: Eje X: | C6: N/A
B7: Eje Y: | C7: N/A
B9: Eje Z: | C9: Periodo Actual
I10: Total [miembro]
I11: Acueducto [miembro] | J11: Alcantarillado [miembro] | K11: Aseo [miembro] | L11: Energía Eléctrica [miembro] | M11: Gas combustible por redes [miembro] | N11: Gas Licuado de Petróleo [miembro] | O11: Otras actividades no vigiladas por la SSPD [miembro] | P11: Operador del sistema y Administrador del mercado de energia (XM) [miembro]
B12: Estado de Situación Financiera por Servicio [partidas]
C13: Activos [resumen]
D14: Activos corrientes [resumen]
E15: Efectivo y equivalentes al efectivo | Q15: =Hoja7!F21+Hoja7!F26+Hoja7!F27
F16: Efectivo y equivalentes al efectivo de uso restringido corriente
E17: Cuentas comerciales por cobrar y otras cuentas por cobrar corrientes [Resumen]
F18: Cuentas comerciales por cobrar por prestación de servicios públicos corrientes [Resumen]
G19: Cuentas comerciales por cobrar corrientes por prestación de servicios públicos corrientes (Sin incluir subsidios ni actividades de aprovechamiento)
G20: Cuentas comerciales por cobrar por subsidios corrientes
H21: Cuentas comerciales por cobrar corrientes del servicio público al Ministerio de Minas por concepto de subsidios
G22: Cuentas comerciales por cobrar por actividad de aprovechamiento corrientes
G23: Total cuentas comerciales por cobrar por prestación de servicios públicos corrientes | I23: =I19+I20 | J23: =J19+J20 | K23: =K19+K20+K22 | L23: =L19+L20 | M23: =M19+M20 | N23: =N19+N20 | O23: =O19 | Q23: =Q19+Q20+Q22
F24: Cuentas comerciales por cobrar por venta de bienes corrientes
F25: Cuentas por cobrar partes relacionadas y asociadas corrientes
F26: Otras cuentas por cobrar corrientes
F27: Total cuentas comerciales por cobrar y otras cuentas por cobrar corrientes | I27: =SUM(I23:I26) | J27: =SUM(J23:J26) | K27: =SUM(K23:K26) | L27: =SUM(L23:L26) | M27: =SUM(M23:M26) | N27: =SUM(N23:N26) | O27: =SUM(O23:O26) | P27: =SUM(P24:P26) | Q27: =SUM(Q23:Q26)
E28: Inventarios corrientes
E29: Activos por impuestos corrientes
E30: Activos biológicos corrientes
E31: Otros activos financieros corrientes
E32: Otros activos no financieros corrientes
E33: Activos corrientes distintos al efectivo pignorados como garantía colateral para las que el receptor de transferencias tiene derecho por contrato o costumbre a vender o pignorar de nuevo dicha garantía colateral
E34: Total activos corrientes distintos de los activos no corrientes o grupo de activos para su disposición clasificados como mantenidos para la venta o como mantenidos para distribuir a los propietarios | I34: =I15+SUM(I27:I33) | J34: =J15+SUM(J27:J33) | K34: =K15+SUM(K27:K33) | L34: =L15+SUM(L27:L33) | M34: =M15+SUM(M27:M33) | N34: =N15+SUM(N27:N33) | O34: =O15+SUM(O27:O33) | P34: =P15+SUM(P27:P33) | Q34: =Q15+SUM(Q27:Q33)
E35: Activos no corrientes o grupos de activos para su disposición clasificados como mantenidos para la venta
E36: Activos no corrientes o grupos de activos para su disposición clasificados como mantenidos para distribuir a los propietarios
E37: Total de activos corrientes | I37: =SUM(I34:I36) | J37: =SUM(J34:J36) | K37: =SUM(K34:K36) | L37: =SUM(L34:L36) | M37: =SUM(M34:M36) | N37: =SUM(N34:N36) | O37: =SUM(O34:O36) | P37: =SUM(P34:P36) | Q37: =SUM(Q34:Q36)
D38: Activos no corrientes [resumen]
E39: Efectivo y equivalentes al efectivo de uso restringido
E40: Propiedades, planta y equipo
E41: Propiedad de inversión
E42: Plusvalía
...

Sheet Hoja3
B2: Indice
B3: Archivo: | C3: I:\Proyectos2025\proyecto_niif\_backup_legacy\Grupo1_Individual_Directo_ID20037_2024-12-31.xbrl
B4: Empresa: | C4: 20037
B5: Vista: | C5: [310000] Estado de Resultados Integral, resultado del periodo, por función del gasto - Individual
B6: Eje X: | C6: N/A
B7: Eje Y: | C7: N/A
B9: Eje Z: | C9: Periodo Actual
F10: Total [miembro]
F11: Acueducto [miembro] | G11: Alcantarillado [miembro] | H11: Aseo [miembro] | I11: Energía Eléctrica [miembro] | J11: Gas combustible por redes [miembro] | K11: Gas Licuado de Petróleo [miembro] | L11: Otras actividades no vigiladas por la SSPD [miembro] | M11: Operador del sistema y Administrador del mercado de energia (XM) [miembro]
B12: Estado de Resultados Integral por Servicio [partidas]
C13: Ganancia (pérdida) [resumen]
D14: Ingresos de actividades ordinarias
D15: Costo de ventas
D16: Ganancia bruta | F16: =-F15+F14 | G16: =-G15+G14 | H16: =-H15+H14 | I16: =-I15+I14 | J16: =-J15+J14 | K16: =-K15+K14 | L16: =-L15+L14 | M16: =-M15+M14 | N16: =-N15+N14
D17: Otros ingresos
D18: Gastos de administración
D19: Otros gastos
D20: Otras ganancias (pérdidas)
D21: Ganancia (pérdida) por actividades de operación | F21: =F16+F17-F18-F19+F20 | G21: =G16+G17-G18-G19+G20 | H21: =H16+H17-H18-H19+H20 | I21: =I16+I17-I18-I19+I20 | J21: =J16+J17-J18-J19+J20 | K21: =K16+K17-K18-K19+K20 | L21: =L16+L17-L18-L19+L20 | M21: =M16+M17-M18-M19+M20 | N21: =N16+N17-N18-N19+N20
D22: Diferencia entre el importe en libros de dividendos pagaderos e importe en libros de activos distribuidos distintos al efectivo
D23: Ganancias (pérdidas) derivadas de la posición monetaria neta
D24: Ganancias (pérdidas) que surgen de la baja en cuentas de activos financieros medidos al costo amortizado
D25: Ingresos financieros
D26: Costos financieros
D27: Deterioro de valor de ganancias y reversión de pérdidas por deterioro de valor (pérdidas por deterioro de valor) determinado de acuerdo con la NIIF 9
D28: Participación en las ganancias (pérdidas) de asociadas y negocios conjuntos que se contabilicen utilizando el método de la participación
D29: Otros ingresos (gastos) procedentes de subsidiarias, entidades controladas de forma conjunta y asociadas
D30: Ganancias (pérdidas) que surgen de diferencias entre importes en libros anteriores y el valor razonable de activos financieros reclasificados como medidos al valor razonable
D31: Ganancia (pérdida) acumulada anteriormente reconocida en otro resultado integral que surge de la reclasificación de activos financieros de la categoría de medición de valor razonable con cambios en otro resultado integral a la de valor razonable con cambios en resultados
D32: Ganancias (pérdidas) de cobertura por cobertura de un grupo de partidas con posiciones de riesgo compensadoras
D33: Ganancia (pérdida), antes de impuestos | F33: =SUM(F21:F25)-F26-F27+SUM(F28:F32) | G33: =SUM(G21:G25)-G26-G27+SUM(G28:G32) | H33: =SUM(H21:H25)-H26-H27+SUM(H28:H32) | I33: =SUM(I21:I25)-I26-I27+SUM(I28:I32) | J33: =SUM(J21:J25)-J26-J27+SUM(J28:J32) | K33: =SUM(K21:K25)-K26-K27+SUM(K28:K32) | L33: =SUM(L21:L25)-L26-L27+SUM(L28:L32) | M33: =SUM(M21:M25)-M26-M27+SUM(M28:M32) | N33: =SUM(N21:N25)-N26-N27+SUM(N28:N32)
D34: Gasto (ingreso) por impuesto a las ganancias corriente
D35: Gasto (ingreso) por impuesto a las ganancias diferido
D36: Ganancia (pérdida) procedente de operaciones continuadas | F36: =F33-F34-F35 | G36: =G33-G34-G35 | H36: =H33-H34-H35 | I36: =I33-I34-I35 | J36: =J33-J34-J35 | K36: =K33-K34-K35 | L36: =L33-L34-L35 | M36: =M33-M34-M35 | N36: =N33-N34-N35
D37: Ganancia (pérdida) procedente de operaciones discontinuadas
D38: Ganancia (pérdida) | F38: =F36+F37 | G38: =G36+G37 | H38: =H36+H37 | I38: =I36+I37 | J38: =J36+J37 | K38: =K36+K37 | L38: =L36+L37 | M38: =M36+M37 | N38: =N36+N37
C39: Ganancias por acción [resumen]
D40: Ganancia por acción básica [resumen]
E41: Ganancia (pérdida) por acción básica en operaciones continuadas
E42: Ganancia (pérdida) por acción básica en operaciones discontinuadas
...

Sheet Hoja4
B2: Indice
B3: Archivo: | C3: I:\Proyectos2025\proyecto_niif\_backup_legacy\Grupo1_Individual_Directo_ID20037_2024-12-31.xbrl
B4: Empresa: | C4: 20037
B5: Vista: | C5: [420000] Estado de Resultados Integral, componentes ORI presentados antes de impuestos - Individual
B6: Eje X: | C6: N/A
B7: Eje Y: | C7: N/A
B8: Eje Z: | C8: N/A
H10: Periodo Actual | I10: Periodo Anterior
B11: Estado del resultado integral [resumen]
C12: Ganancia (pérdida) | H12: =Hoja3!N36+Hoja3!N37 | I12: =Hoja3!N76+Hoja3!N77
C13: Otro resultado integral [resumen]
D14: Componentes de otro resultado integral que no se reclasificarán al resultado del periodo, antes de impuestos [resumen]
E15: Otro resultado integral, antes de impuestos, ganancias (pérdidas) de inversiones en instrumentos de patrimonio
E16: Otro resultado integral, antes de impuestos, ganancias (pérdidas) por nueva evaluación de las propiedades, planta y equipo, activos por derecho de uso y activos intangibles
E17: Otro resultado integral, antes de impuestos, ganancias (pérdidas) por nuevas mediciones de planes de beneficios definidos
E18: Otro resultado integral, antes de impuestos, diferencias de cambio en la conversión, distinto de la conversión de negocios en el extranjero
E19: Otro resultado integral, antes de impuestos, cambio en el valor razonable de pasivos financieros atribuible a cambios en el riesgo crediticio del pasivo
E20: Otro resultado integral, antes de impuestos, ganancias (pérdidas) por instrumentos de cobertura que cubren inversiones en instrumentos de patrimonio
E21: Otro resultado integral, antes de impuestos, ingresos (gastos) financieros por contratos de seguro emitidos excluidos del resultado del periodo que no se reclasificará al resultado del periodo
D22: Participación de otro resultado integral de asociadas y negocios conjuntos contabilizados utilizando el método de la participación que no se reclasificará al resultado del periodo, antes de impuestos
D23: Total otro resultado integral que no se reclasificará al resultado del periodo, antes de impuestos | H23: =SUM(H15:H22) | I23: =SUM(I15:I22)
D24: Componentes de otro resultado integral que se reclasificarán al resultado del periodo, antes de impuestos [resumen]
E25: Diferencias de cambio por conversión [resumen]
F26: Ganancias (pérdidas) por diferencias de cambio en la conversión de negocios en el extranjero, antes de impuestos
F27: Ajustes de reclasificación por diferencias de cambio en la conversión de negocios en el extranjero, antes de impuestos
F28: Otro resultado integral, antes de impuestos, diferencias de cambio en la conversión de negocios en el extranjero | H28: =-H27+H26 | I28: =-I27+I26
E29: Activos financieros disponibles para la venta [resumen]
F30: Ganancias (pérdidas) por nuevas mediciones de activos financieros disponibles para la venta, antes de impuestos
F31: Ajustes de reclasificación, activos financieros disponibles para la venta, antes de impuestos
F32: Otro resultado integral antes de impuestos, activos financieros disponibles para la venta | H32: =H30-H31 | I32: =I30-I31
E33: Coberturas del flujo de efectivo [resumen]
F34: Ganancias (pérdidas) por coberturas de flujos de efectivo, antes de impuestos
F35: Ajustes de reclasificación en coberturas de flujos de efectivo, antes de impuestos
F36: Importes eliminados del patrimonio e incluidos en el importe en libros de activos (pasivos) no financieros que se hayan adquirido o incurrido mediante una transacción prevista altamente probable cubierta, antes de impuestos
F37: Otro resultado integral, antes de impuestos, coberturas del flujo de efectivo | H37: =H34-H35-H36 | I37: =I34-I35-I36
E38: Coberturas de inversiones netas en negocios en el extranjero [resumen]
F39: Ganancias (pérdidas) por coberturas de inversiones netas en negocios en el extranjero, antes de impuestos
F40: Ajustes de reclasificación por coberturas de inversiones netas en negocios en el extranjero, antes de impuestos
F41: Otro resultado integral, antes de impuestos, coberturas de inversiones netas en negocios en el extranjero | H41: =-H40+H39 | I41: =-I40+I39
E42: Costo de la cobertura [resumen]
...

Sheet Hoja5
B2: Indice
B3: Archivo: | C3: I:\Proyectos2025\proyecto_niif\_backup_legacy\Grupo1_Individual_Directo_ID20037_2024-12-31.xbrl
B4: Empresa: | C4: 20037
B5: Vista: | C5: [510000] Estado de flujos de efectivo, método directo - Individual
B6: Eje X: | C6: N/A
B7: Eje Y: | C7: N/A
B9: Eje Z: | C9: Periodo Actual
F10: Total [miembro]
F11: Acueducto [miembro] | G11: Alcantarillado [miembro] | H11: Aseo [miembro] | I11: Energía Eléctrica [miembro] | J11: Gas combustible por redes [miembro] | K11: Gas Licuado de Petróleo [miembro] | L11: Otras actividades no vigiladas por la SSPD [miembro] | M11: Operador del sistema y Administrador del mercado de energia (XM) [miembro]
B12: Estado de Flujo de Efectivo por Servicio [partidas]
C13: Flujos de efectivo procedentes de (utilizados en) actividades de operación [resumen]
D14: Clases de cobros por actividades de operación [resumen]
E15: Cobros procedentes de las ventas de bienes y prestación de servicios
E16: Cobros procedentes de regalías, cuotas, comisiones y otros ingresos de actividades ordinarias
E17: Cobros derivados de contratos mantenidos para intermediación o para negociar con ellos
E18: Cobros procedentes de primas y prestaciones, anualidades y otros beneficios de pólizas suscritas
E19: Cobros por rentas y ventas posteriores de activos mantenidos para arrendar a terceros y posteriormente mantenidos para la venta
E20: Otros cobros por actividades de operación
D21: Clases de pagos en efectivo procedentes de actividades de operación [resumen]
E22: Pagos a proveedores por el suministro de bienes y servicios
E23: Pagos procedentes de contratos mantenidos para intermediación o para negociar
E24: Pagos a y por cuenta de los empleados
E25: Pagos por primas y prestaciones, anualidades y otras obligaciones derivadas de las pólizas suscritas
E26: Pagos por producir o adquirir activos mantenidos para arrendar a terceros y posteriormente mantenidos para la venta
E27: Otros pagos por actividades de operación
D28: Flujos de efectivo netos procedentes (utilizados en) operaciones | F28: =SUM(F15:F20)-SUM(F22:F27) | G28: =SUM(G15:G20)-SUM(G22:G27) | H28: =SUM(H15:H20)-SUM(H22:H27) | I28: =SUM(I15:I20)-SUM(I22:I27) | J28: =SUM(J15:J20)-SUM(J22:J27) | K28: =SUM(K15:K20)-SUM(K22:K27) | L28: =SUM(L15:L20)-SUM(L22:L27) | M28: =SUM(M15:M20)-SUM(M22:M27) | N28: =SUM(N15:N20)-SUM(N22:N27)
D29: Dividendos pagados
D30: Dividendos recibidos
D31: Intereses pagados
D32: Intereses recibidos
D33: Impuestos a las ganancias reembolsados (pagados)
D34: Otras entradas (salidas) de efectivo
D35: Flujos de efectivo netos procedentes de (utilizados en) actividades de operación | F35: =F34+F30-F29+F32-F31-F33+F28 | G35: =G34+G30-G29+G32-G31-G33+G28 | H35: =H34+H30-H29+H32-H31-H33+H28 | I35: =I34+I30-I29+I32-I31-I33+I28 | J35: =J34+J30-J29+J32-J31-J33+J28 | K35: =K34+K30-K29+K32-K31-K33+K28 | L35: =L34+L30-L29+L32-L31-L33+L28 | M35: =M34+M30-M29+M32-M31-M33+M28 | N35: =N34+N30-N29+N32-N31-N33+N28
C36: Flujos de efectivo procedentes de (utilizados en) actividades de inversión [resumen]
D37: Flujos de efectivo procedentes de la pérdida de control de subsidiarias u otros negocios
D38: Flujos de efectivo utilizados para obtener el control de subsidiarias u otros negocios
D39: Otros cobros por la venta de patrimonio o instrumentos de deuda de otras entidades
D40: Otros pagos para adquirir patrimonio o instrumentos de deuda de otras entidades
D41: Otros cobros por la venta de participaciones en negocios conjuntos
D42: Otros pagos para adquirir participaciones en negocios conjuntos
...

Sheet Hoja6
B2: Indice
B3: Archivo: | C3: I:\Proyectos2025\proyecto_niif\_backup_legacy\Grupo1_Individual_Directo_ID20037_2024-12-31.xbrl
B4: Empresa: | C4: 20037
B5: Vista: | C5: [610000] Estado de cambios en el patrimonio - Individual
B6: Eje X: | C6: N/A
B7: Eje Y: | C7: N/A
B9: Eje Z: | C9: Periodo Actual
F10: Patrimonio [miembro]
F11: Capital emitido [miembro] | G11: Acciones propias en cartera [miembro] | H11: Prima de emisión [miembro] | I11: Ganancias acumuladas [miembro] | J11: Total otras reservas [miembro] | Q11: Otras partidas patrimoniales [miembro] | AI11: Otras participaciones en el patrimonio (No ORI) [miembro]
J12: Reserva legal [miembro] | K12: Reserva para catástrofes [miembro] | L12: Reserva para estabilización [miembro] | M12: Reserva de componentes de participación discrecional [miembro] | N12: Reserva de pagos basados en acciones [miembro] | O12: Otras reservas [miembro] | Q12: Reserva de ganancias y pérdidas por inversiones en instrumentos de patrimonio [miembro] | R12: Importes reconocidos en otro resultado integral y acumulados en el patrimonio relativos a activos no corrientes o grupos de activos para su disposición mantenidos para la venta [miembro] | S12: Superávit de revaluación [miembro] | T12: Reserva de nuevas mediciones de planes de beneficios definidos [miembro] | U12: Reserva para cambios en el valor razonable de pasivos financieros atribuibles a cambios en el riesgo crediticio del pasivo [miembro] | V12: Reserva de ganancias y pérdidas sobre instrumentos de cobertura que cubren inversiones en instrumentos de patrimonio [miembro] | W12: Reserva de diferencias de cambio en conversiones [miembro] | X12: Participación de otro resultado integral de asociadas y negocios conjuntos contabilizados utilizando el método de la participación [miembro] | Y12: Reserva de ganancias y pérdidas en nuevas mediciones de activos financieros disponibles para la venta [miembro] | Z12: Reserva de coberturas de flujo de efectivo [miembro] | AA12: Reserva de coberturas de inversiones netas en negocios en el extranjero [miembro] | AB12: Reserva por cambios en el valor temporal del dinero de opciones [miembro] | AC12: Reserva por cambios en el valor de los elementos a término de contratos a término [miembro] | AD12: Reserva por cambios en el valor de los diferenciales de la tasa de cambio de la moneda extranjera [miembro] | AE12: Reserva de ingresos (gastos) financieros por contratos de reaseguro mantenidos, excluidos del resultado del periodo [miembro] | AF12: Reserva de ingresos (gastos) financieros por contratos de seguro emitidos excluidos del resultado del periodo que no se reclasificará al resultado del periodo [miembro] | AG12: Reversión de ganancias y pérdidas sobre activos financieros medidos al valor razonable con cambios en otro resultado integral [miembro]
B13: Estado de cambios en el patrimonio [partidas]
C14: Patrimonio al comienzo del periodo | AJ14: =Hoja2!Q218+Hoja2!Q219-Hoja2!Q220+Hoja2!Q221+Hoja2!Q222+SUM(Hoja2!Q224:Q227)
C15: Incremento (disminución) por cambios en políticas contables
C16: Incremento (disminución) por correcciones de errores de periodos anteriores
C17: Patrimonio al comienzo del periodo incluyendo reexpresión. (Si la hubo).
C18: Cambios en el patrimonio [resumen]
D19: Resultado integral [resumen]
E20: Ganancia (pérdida) | AJ20: =Hoja3!N36+Hoja3!N37
E21: Otro resultado integral | AJ21: =Hoja4!H70-Hoja4!H79-Hoja4!H80-Hoja4!H92-Hoja4!H93
E22: Resultado integral total | F22: =F20+F21 | G22: =G20+G21 | H22: =H20+H21 | I22: =I20+I21 | J22: =J20+J21 | K22: =K20+K21 | L22: =L20+L21 | M22: =M20+M21 | ... AJ22: =AJ20+AJ21
D23: Emisión de patrimonio
D24: Dividendos reconocidos como distribuciones a los propietarios
D25: Incrementos por otras aportaciones de los propietarios, patrimonio
D26: Disminución por otras distribuciones a los propietarios, patrimonio
D27: Incrementos (disminuciones) por otros cambios, patrimonio
D28: Incrementos (disminuciones) por transacciones con acciones propias, patrimonio
D29: Incrementos (disminuciones) por cambios las participaciones en la propiedad de subsidiarias que no dan lugar a pérdida de control, patrimonio
D30: Incrementos (disminuciones) por transacciones con pagos basados en acciones, patrimonio
D31: Importe eliminado de reservas de coberturas de flujos de efectivo e incluido en el costo inicial u otro importe en libros de activos (pasivos) no financieros o compromisos en firme para los que se aplica la contabilidad de coberturas del valor razonable
D32: Importe eliminado de reservas de cambios en el valor temporal del dinero de opciones e incluido en el costo inicial u otro importe en libros de activos (pasivos) no financieros o compromisos en firme para los que se aplica la contabilidad de coberturas del valor razonable
D33: Importe eliminado de reservas de cambios en el valor de los elementos a término de contratos a término e incluido en el costo inicial u otro importe en libros de activos (pasivos) no financieros o compromisos en firme para los que se aplica la contabilidad de coberturas del valor razonable
D34: Importe eliminado de reservas de cambios en el valor de los diferenciales de tasa cambio de moneda extranjera e incluido en el costo inicial u otro importe en libros de activos (pasivos) no financieros o compromisos en firme para los que se aplica la contabilidad de coberturas del valor razonable
D35: Total incremento (disminución) en el patrimonio | F35: =F22+F23-F24+F25-F26+SUM(F27:F30)-SUM(F31:F34) | G35: =G22+G23-G24+G25-G26+SUM(G27:G30)-SUM(G31:G34) | H35: =H22+H23-H24+H25-H26+SUM(H27:H30)-SUM(H31:H34) | I35: =I22+I23-I24+I25-I26+SUM(I27:I30)-SUM(I31:I34) | J35: =J22+J23-J24+J25-J26+SUM(J27:J30)-SUM(J31:J34) | K35: =K22+K23-K24+K25-K26+SUM(K27:K30)-SUM(K31:K34) | L35: =L22+L23-L24+L25-L26+SUM(L27:L30)-SUM(L31:L34) | M35: =M22+M23-M24+M25-M26+SUM(M27:M30)-SUM(M31:M34) | ... AJ35: =AJ22+AJ23-AJ24+AJ25-AJ26+SUM(AJ27:AJ30)-SUM(AJ31:AJ34)
C36: Patrimonio al final del periodo | AJ36: =Hoja2!Q107+Hoja2!Q108-Hoja2!Q109+Hoja2!Q110+Hoja2!Q111+SUM(Hoja2!Q113:Q116)
B38: Eje Z: | C38: Periodo Anterior
F39: Patrimonio [miembro]
F40: Capital emitido [miembro] | G40: Acciones propias en cartera [miembro] | H40: Prima de emisión [miembro] | I40: Ganancias acumuladas [miembro] | J40: Total otras reservas [miembro] | Q40: Otras partidas patrimoniales [miembro] | AI40: Otras participaciones en el patrimonio (No ORI) [miembro]
J41: Reserva legal [miembro] | K41: Reserva para catástrofes [miembro] | L41: Reserva para estabilización [miembro] | M41: Reserva de componentes de participación discrecional [miembro] | N41: Reserva de pagos basados en acciones [miembro] | O41: Otras reservas [miembro] | Q41: Reserva de ganancias y pérdidas por inversiones en instrumentos de patrimonio [miembro] | R41: Importes reconocidos en otro resultado integral y acumulados en el patrimonio relativos a activos no corrientes o grupos de activos para su disposición mantenidos para la venta [miembro] | S41: Superávit de revaluación [miembro] | T41: Reserva de nuevas mediciones de planes de beneficios definidos [miembro] | U41: Reserva para cambios en el valor razonable de pasivos financieros atribuibles a cambios en el riesgo crediticio del pasivo [miembro] | V41: Reserva de ganancias y pérdidas sobre instrumentos de cobertura que cubren inversiones en instrumentos de patrimonio [miembro] | W41: Reserva de diferencias de cambio en conversiones [miembro] | X41: Participación de otro resultado integral de asociadas y negocios conjuntos contabilizados utilizando el método de la participación [miembro] | Y41: Reserva de ganancias y pérdidas en nuevas mediciones de activos financieros disponibles para la venta [miembro] | Z41: Reserva de coberturas de flujo de efectivo [miembro] | AA41: Reserva de coberturas de inversiones netas en negocios en el extranjero [miembro] | AB41: Reserva por cambios en el valor temporal del dinero de opciones [miembro] | AC41: Reserva por cambios en el valor de los elementos a término de contratos a término [miembro] | AD41: Reserva por cambios en el valor de los diferenciales de la tasa de cambio de la moneda extranjera [miembro] | AE41: Reserva de ingresos (gastos) financieros por contratos de reaseguro mantenidos, excluidos del resultado del periodo [miembro] | AF41: Reserva de ingresos (gastos) financieros por contratos de seguro emitidos excluidos del resultado del periodo que no se reclasificará al resultado del periodo [miembro] | AG41: Reversión de ganancias y pérdidas sobre activos financieros medidos al valor razonable con cambios en otro resultado integral [miembro]
B42: Estado de cambios en el patrimonio [partidas]
C43: Patrimonio al comienzo del periodo
...

Sheet Hoja7
B2: Indice
B3: Archivo: | C3: I:\Proyectos2025\proyecto_niif\_backup_legacy\Grupo1_Individual_Directo_ID20037_2024-12-31.xbrl
B4: Empresa: | C4: 20037
B5: Vista: | C5: [800100] Notas - Subclasificaciones de activos, pasivos y patrimonios
B6: Eje X: | C6: N/A
B7: Eje Y: | C7: N/A
B8: Eje Z: | C8: N/A
F10: Periodo Actual
B11: Subclasificaciones de activos, pasivos y patrimonios [resumen]
C12: Inversiones en subsidiarias, negocios conjuntos y asociadas presentadas en los estados financieros separados [resumen]
D13: Inversiones en subsidiarias presentadas en estados financieros separados | F13: =Hoja2!Q46
D14: Inversiones en negocios conjuntos presentadas en estados financieros separados | F14: =Hoja2!Q47
D15: Inversiones en asociadas presentadas en estados financieros separados | F15: =Hoja2!Q45
D16: Total de inversiones en subsidiarias, negocios conjuntos y asociadas en los estados financieros separados | F16: =SUM(F13:F15)
C17: Efectivo y equivalentes al efectivo [resumen]
D18: Efectivo [resumen]
E19: Efectivo en caja
E20: Saldos en bancos
E21: Total efectivo | F21: =F19+F20
D22: Equivalentes al efectivo [resumen]
E23: Depósitos a corto plazo, clasificados como equivalentes al efectivo
E24: Inversiones a corto plazo, clasificados como equivalentes al efectivo
E25: Otros acuerdos bancarios, clasificados como equivalentes al efectivo
E26: Total equivalentes al efectivo | F26: =SUM(F23:F25)
D27: Otro efectivo y equivalentes al efectivo
D28: Total de efectivo y equivalentes al efectivo | F28: =F21+F26+F27
C29: Préstamos tomados [resumen]
D30: Parte no corriente de préstamos no corrientes
D31: Préstamos corrientes y parte corriente de préstamos no corrientes [resumen]
E32: Préstamos corrientes
E33: Parte corriente de préstamos no corrientes
E34: Total préstamos corrientes y parte corriente de préstamos no corrientes | F34: =F32+F33
D35: Total préstamos | F35: =F30+F34

Sheet Hoja8
B2: Indice
B3: Archivo: | C3: I:\Proyectos2025\proyecto_niif\_backup_legacy\Grupo1_Individual_Directo_ID20037_2024-12-31.xbrl
B4: Empresa: | C4: 20037
B5: Vista: | C5: [800500] Notas - Lista de Notas
B6: Eje X: | C6: N/A
B7: Eje Y: | C7: N/A
B8: Eje Z: | C8: N/A
D10: Periodo Actual
B11: Información a revelar sobre notas y otra información explicativa [bloque de texto]
C12: Información a revelar sobre juicios y estimaciones contables [bloque de texto]
C13: Información a revelar sobre gastos acumulados (devengados) y otros pasivos [bloque de texto]
C14: Información a revelar sobre correcciones de valor por pérdidas crediticias [bloque de texto]
C15: Información a revelar sobre asociadas [bloque de texto]
C16: Información a revelar sobre remuneración de los auditores [bloque de texto]
C17: Información a revelar sobre la autorización de los estados financieros [bloque de texto]
C18: información a revelar sobre activos financieros disponibles para la venta [bloque de texto]
C19: Información a revelar sobre criterios de consolidación [bloque de texto]
C20: Información a revelar sobre criterios de elaboración de los estados financieros [bloque de texto]
C21: Información a revelar sobre préstamos [bloque de texto]
C22: Información a revelar sobre combinaciones de negocios [bloque de texto]
C23: Información a revelar sobre saldos bancarios y de efectivo en bancos centrales [bloque de texto]
... C132: Información a revelar sobre derechos a participaciones que surgen de fondos de desmantelamiento, restauración y la rehabilitación medioambiental [bloque de texto]

Sheet Hoja9
B2: Indice
B3: Archivo: | C3: I:\Proyectos2025\proyecto_niif\_backup_legacy\Grupo1_Individual_Directo_ID20037_2024-12-31.xbrl
B4: Empresa: | C4: 20037
B5: Vista: | C5: [800600] Notas - Lista de políticas contables
B6: Eje X: | C6: N/A
B7: Eje Y: | C7: N/A
B8: Eje Z: | C8: N/A
D10: Periodo Actual
B11: Información a revelar sobre las políticas contables significativas [bloque de texto]
C12: Descripción de la política contable para activos financieros disponibles para la venta [bloque de texto]
C13: Descripción de la política contable para costos de préstamos [bloque de texto]
C14: Descripción de la política contable para préstamos [bloque de texto]
C15: Descripción de la política contable para combinaciones de negocios y plusvalía [bloque de texto]
C16: Descripción de la política contable para flujos de efectivo [bloque de texto]
C17: Descripción de la política contable para construcciones en proceso [bloque de texto]
C18: Descripción de la política contable para pasivos contingentes y activos contingentes [bloque de texto]
C19: Descripción de la política contable para provisiones para retiro del servicio, restauración y rehabilitación [bloque de texto]
C20: Descripción de la política contable para impuesto a las ganancias diferido [bloque de texto]
C21: Descripción de la política contable para gastos por depreciación [bloque de texto]
C22: Descripción de la política contable para baja en cuentas de instrumentos financieros [bloque de texto]
C23: Descripción de la política contable para instrumentos financieros derivados y coberturas [bloque de texto]
... C81: Descripción de otras políticas contables relevantes para comprender los estados financieros [bloque de texto]

Sheet Hoja10
B2: Indice
B3: Archivo: | C3: I:\Proyectos2025\proyecto_niif\_backup_legacy\Grupo1_Individual_Directo_ID20037_2024-12-31.xbrl
B4: Empresa: | C4: 20037
B5: Vista: | C5: [810000] Notas - Información de la entidad y declaración de cumplimiento con el marco normativo
B6: Eje X: | C6: N/A
B7: Eje Y: | C7: N/A
B8: Eje Z: | C8: N/A
F10: Periodo Actual
B11: Información a revelar sobre notas y otra información explicativa [bloque de texto]
C12: Sede de la entidad
C13: Forma legal de la entidad
C14: País de constitución
C15: Ciudad donde se encuentra ubicada la sede administrativa
C16: Dirección de la sede administrativa de la entidad
C17: E-mail corporativo
C18: Número de empleados
C19: Número promedio de empleados
C20: Descripción de la naturaleza de las operaciones de la entidad y actividades principales
C21: Nombre de la entidad controladora
C22: Nombre de la controladora última del grupo
C23: Fecha establecida de duración de la entidad, para entidades de vida limitada
... C33: Hubo reclasificaciones que den lugar a variaciones en los valores certificados en el periodo anterior frente al comparado del periodo actual que se está presentando
D34: Explicación de reclasificaciones que den lugar a variaciones en los valores certificados en el periodo anterior frente al comparado del periodo actual que se está presentando
D35: Importe de reclasificaciones o cambios en la presentación
D36: Descripción de la naturaleza de los ajustes necesarios para presentar información comparativa
C37: Información a revelar sobre finalización de la prestación de los servicios inscritos en RUPS [resumen]
D38: Información a revelar sobre incertidumbres sobre la capacidad de dar continuidad a la prestación de uno o más servicios inscritos en RUPS
D39: ¿Durante el periodo sobre el que se informa se finalizó la prestación de uno o más servicios inscritos en RUPS?
E40: Detalle sobre la finalización de la prestación de los servicios inscritos en RUPS. (indicar servicio y fecha de finalización del servicio, indicar si otra empresa de servicios públicos tomó la prestación del servicio, ¿cuál?)
C41: Descripción del hecho de que los importes presentados en los estados financieros no son totalmente comparables
C42: Información relacionada con Objetivos de Desarrollo Sostenible impulsadas por la Organización de Naciones Unidas [Abstracto]
D43: La entidad ha implementado programas, prácticas o políticas relacionados con objetivos de desarrollo sostenible?
D44: La entidad prepara reportes de sostenibilidad?
D45: Si lo presenta como reporte a una entidad de supervisión específica, a cuál?
D46: La entidad cuenta con objetivos de desarrollo sostenible para el eje económico?
D47: Mencione que indicadores calcula. Explique los elementos que componen cada indicador.

Sheet Hoja11
B2: Indice
B3: Archivo: | C3: I:\Proyectos2025\proyecto_niif\_backup_legacy\Grupo1_Individual_Directo_ID20037_2024-12-31.xbrl
B4: Empresa: | C4: 20037
B5: Vista: | C5: [811001] Notas - Cambios por políticas contables, estimaciones contables o corrección de errores
B6: Eje X: | C6: N/A
B7: Eje Y: | C7: N/A
B8: Eje Z: | C8: Periodo Actual
C10: Detalle de los cambios en políticas contables, estimaciones contables y errores [Resumen]
C11: Tipo de Cambio por politica, estimación o corrección de error | D11: Descripción del cambio en política, estimación o corrección de error | E11: Impacto en el activo por cambio por política, estimación o corrección de error | F11: Impacto en el pasivo por cambio por política, estimación o corrección de error | G11: Impacto en el patrimonio por cambio por política, estimación o corrección de error | H11: Impacto en el resultado por cambio por política, estimación o corrección de error
B12: # Fila de cambio por política, estimación o error

Sheet Hoja12
B2: Indice
B3: Archivo: | C3: I:\Proyectos2025\proyecto_niif\_backup_legacy\Grupo1_Individual_Directo_ID20037_2024-12-31.xbrl
B4: Empresa: | C4: 20037
B5: Vista: | C5: [822100] Notas - Propiedades, planta y equipo - Bloques de texto
B6: Eje X: | C6: N/A
B7: Eje Y: | C7: N/A
B8: Eje Z: | C8: N/A
D10: Periodo Actual
B11: Información a revelar sobre propiedades, planta y equipo [bloque de texto]
C12: Información a revelar detallada sobre propiedades, planta y equipo [bloque de texto]
C13: Propiedades, planta y equipo, restricciones en la titularidad
C14: Descripción de la existencia de restricciones en la titularidad, propiedades, planta y equipo
C15: Propiedades, planta y equipo, pignoradas como garantía
C16: Compromisos contractuales para la adquisición de propiedades, planta y equipo

Sheet Hoja13
B2: Indice
B3: Archivo: | C3: I:\Proyectos2025\proyecto_niif\_backup_legacy\Grupo1_Individual_Directo_ID20037_2024-12-31.xbrl
B4: Empresa: | C4: 20037
B5: Vista: | C5: [822100a] Notas - Propiedades, planta y equipo - Información a revelar
B6: Eje X: | C6: N/A
B7: Eje Y: | C7: N/A
B8: Eje Z: | C8: Periodo Actual
F10: Propiedades, planta y equipo [miembro]
F11: Terrenos y construcciones [miembro] | H11: Maquinaria [miembro] | I11: Vehículos [miembro] | J11: Enseres y accesorios [miembro] | K11: Equipo de oficina [miembro] | L11: Equipos informáticos [miembro] | M11: Equipos de redes y comunicación [miembro] | N11: Construcciones en proceso [miembro] | O11: Información complementaria [miembro] | T11: Otras propiedades, planta y equipo [miembro]
F12: Terrenos [miembro] | G12: Edificios [miembro] | O12: Plantas [miembro] | P12: Ductos [miembro] | Q12: Vías [miembro] | R12: Redes y Cables [miembro] | S12: Relleno sanitario [miembro]
B13: Información a revelar detallada sobre propiedades, planta y equipo [partidas]
C14: Bases de medición, propiedades, planta y equipo
C15: Método de depreciación, propiedades, planta y equipo
C16: Vidas útiles o tasas de depreciación, propiedades, planta y equipo
C17: Fechas de vigencia de revaluación, propiedades, planta y equipo
C18: Explicación de la implicación del tasador independiente en la revaluación, propiedades, planta y equipo
C19: Conciliación de cambios en propiedades, planta y equipo [resumen]
D20: Propiedades, planta y equipo al comienzo del periodo | U20: =Hoja2!Q151
D21: Cambios en propiedades, planta y equipo [resumen]
E22: Incrementos distintos de los procedentes de combinaciones de negocios, propiedades, planta y equipo
E23: Adquisiciones realizadas mediante combinaciones de negocios, propiedades, planta y equipo
E24: Incremento (disminución) por diferencias de cambio netas, propiedades, planta y equipo
E25: Depreciación, propiedades, planta y equipo
E26: Pérdidas por deterioro de valor reconocidas en el resultado del periodo, propiedades, planta y equipo
E27: Reversión de pérdidas por deterioro de valor reconocidas en el resultado del periodo, propiedades, planta y equipo
E28: Incrementos (disminuciones) de revaluaciones, propiedades, planta y equipo
E29: Pérdidas por deterioro de valor reconocidas en otro resultado integral, propiedades, planta y equipo
E30: Reversión de pérdidas por deterioro de valor reconocidas en otro resultado integral, propiedades, planta y equipo
E31: Disposiciones y retiros de servicio, propiedades, planta y equipo
E32: Disminuciones por clasificar como mantenidos para la venta, propiedades, planta y equipo
E33: Incrementos (disminuciones) por otros cambios, propiedades, planta y equipo
E34: Total incremento (disminución) en propiedades, planta y equipo | F34: =SUM(F22:F24)-F25-F26+F27+F28-F29+F30-F31-F32+F33 | G34: =SUM(G22:G24)-G25-G26+G27+G28-G29+G30-G31-G32+G33 | H34: =SUM(H22:H24)-H25-H26+H27+H28-H29+H30-H31-H32+H33 | I34: =SUM(I22:I24)-I25-I26+I27+I28-I29+I30-I31-I32+I33 | J34: =SUM(J22:J24)-J25-J26+J27+J28-J29+J30-J31-J32+J33 | K34: =SUM(K22:K24)-K25-K26+K27+K28-K29+K30-K31-K32+K33 | L34: =SUM(L22:L24)-L25-L26+L27+L28-L29+L30-L31-L32+L33 | M34: =SUM(M22:M24)-M25-M26+M27+M28-M29+M30-M31-M32+M33 | ... U34: =SUM(U22:U24)-U25-U26+U27+U28-U29+U30-U31-U32+U33
D35: Propiedades, planta y equipo al final del periodo | U35: =Hoja2!Q40
C36: Información adicional [resumen]
D37: Propiedades, planta y equipo, desembolsos reconocidos en el curso de su construcción.
D38: Propiedades, planta y equipo, ociosos temporalmente.
D39: Propiedades, planta y equipo, importe en libros en términos brutos de los activos depreciados en su totalidad todavía en uso.
D40: Propiedades, planta y equipo, activos retirados del uso activo y no clasificados como mantenidos para la venta.
C41: Propiedades, planta y equipo, revaluación [resumen]
D42: Propiedades, planta y equipo, activos revaluados.
...

Sheet Hoja14
B2: Indice
B3: Archivo: | C3: I:\Proyectos2025\proyecto_niif\_backup_legacy\Grupo1_Individual_Directo_ID20037_2024-12-31.xbrl
B4: Empresa: | C4: 20037
B5: Vista: | C5: [822390] Notas - Instrumentos financieros - Bloques de texto
B6: Eje X: | C6: N/A
B7: Eje Y: | C7: N/A
B8: Eje Z: | C8: N/A
D10: Periodo Actual
B11: Información a revelar sobre instrumentos financieros [bloque de texto]
C12: Información a revelar de activos financieros [bloque de texto]
C13: Información a revelar sobre pasivos financieros [bloque de texto]
C14: Información a revelar detallada sobre coberturas [bloque de texto]

Sheet Hoja15
B2: Indice
B3: Archivo: | C3: I:\Proyectos2025\proyecto_niif\_backup_legacy\Grupo1_Individual_Directo_ID20037_2024-12-31.xbrl
B4: Empresa: | C4: 20037
B5: Vista: | C5: [822390a] Notas - Instrumentos financieros - Activos financieros
B6: Eje X: | C6: N/A
B7: Eje Y: | C7: N/A
B8: Eje Z: | C8: Periodo Actual
D10: Activos financieros, categoría [miembro]
D11: Activos financieros al valor razonable con cambios en resultados, categoría [miembro] | E11: Activos financieros disponibles para la venta, categoría [miembro] | F11: Inversiones mantenidas hasta el vencimiento, categoría [miembro] | G11: Préstamos y cuentas por cobrar, categoría [miembro] | H11: Activos financieros al costo amortizado, categoría [miembro] | I11: Activos financieros al valor razonable con cambios en otro resultado integral, categoría [miembro] | J11: Inversiones en instrumentos de patrimonio designadas a valor razonable con cambios en otro resultado integral [miembro]
B12: Información a revelar sobre activos financieros [partidas]
C13: Activos financieros
C14: Activos financieros, al valor razonable
C15: Importe nocional
C16: Pérdidas por deterioro de valor, activos financieros

Sheet Hoja16
B2: Indice
B3: Archivo: | C3: I:\Proyectos2025\proyecto_niif\_backup_legacy\Grupo1_Individual_Directo_ID20037_2024-12-31.xbrl
B4: Empresa: | C4: 20037
B5: Vista: | C5: [822390b] Notas - Instrumentos financieros - Pasivos financieros
B6: Eje X: | C6: N/A
B7: Eje Y: | C7: N/A
B8: Eje Z: | C8: Periodo Actual
D10: Pasivos financieros, categoría [miembro]
D11: Pasivos financieros al valor razonable con cambios en resultados, categoría [miembro] | E11: Pasivos financieros al costo amortizado, categoría [miembro] | F11: Pasivos financieros que quedan fuera del alcance de la NIIF 7 [miembro]
B12: Información a revelar sobre pasivos financieros [partidas de los estados financieros]
C13: Pasivos financieros
C14: Pasivos financieros, al valor razonable

Sheet Hoja17
B2: Indice
B3: Archivo: | C3: I:\Proyectos2025\proyecto_niif\_backup_legacy\Grupo1_Individual_Directo_ID20037_2024-12-31.xbrl
B4: Empresa: | C4: 20037
B5: Vista: | C5: [822390c] Notas - Instrumentos financieros - Coberturas
B6: Eje X: | C6: N/A
B7: Eje Y: | C7: N/A
B8: Eje Z: | C8: Periodo Actual
D10: Coberturas [miembro]
D11: Coberturas del valor razonable [miembro] | E11: Coberturas del flujo de efectivo [miembro] | F11: Coberturas de inversiones netas en negocios en el extranjero [miembro]
B12: Información a revelar detallada sobre coberturas [partidas]
C13: Descripción del tipo de cobertura
C14: Descripción de instrumentos financieros designados como instrumentos de cobertura
C15: Descripción de la naturaleza de los riesgos que han sido cubiertos
C16: Instrumentos financieros designados como instrumentos de cobertura

Sheet Hoja18
B2: Indice
B3: Archivo: | C3: I:\Proyectos2025\proyecto_niif\_backup_legacy\Grupo1_Individual_Directo_ID20037_2024-12-31.xbrl
B4: Empresa: | C4: 20037
B5: Vista: | C5: [823000] Notas - Medición del valor razonable
B6: Eje X: | C6: N/A
B7: Eje Y: | C7: N/A
B8: Eje Z: | C8: N/A
D10: Periodo Actual
B11: Información a revelar sobre medición del valor razonable [bloque de texto]
C12: Información a revelar sobre medición del valor razonable de activos [bloque de texto]
C13: Información a revelar sobre medición del valor razonable de pasivos [bloque de texto]
C14: Información a revelar sobre medición del valor razonable del patrimonio [bloque de texto]
C15: Información a revelar sobre datos de entrada no observables significativos utilizados en la medición del valor razonable de activos [bloque de texto]
C16: Información a revelar sobre datos de entrada no observables significativos utilizados en la medición del valor razonable de pasivos [bloque de texto]
C17: Información a revelar sobre datos de entrada no observables significativos utilizados en la medición del valor razonable del patrimonio [bloque de texto]

Sheet Hoja19
B2: Indice
B3: Archivo: | C3: I:\Proyectos2025\proyecto_niif\_backup_legacy\Grupo1_Individual_Directo_ID20037_2024-12-31.xbrl
B4: Empresa: | C4: 20037
B5: Vista: | C5: [823180] Notas - Activos intangibles - Información descriptiva
B6: Eje X: | C6: N/A
B7: Eje Y: | C7: N/A
B8: Eje Z: | C8: N/A
D10: Periodo Actual
B11: Información a revelar detallada sobre activos intangibles [resumen]
C12: Información a revelar detallada sobre activos intangibles [bloque de texto]
C13: Información a revelar sobre activos intangibles con vidas útiles indefinidas [bloque de texto]
C14: Activos intangibles con vidas útiles indefinidas
C15: Descripción de los activos intangibles con vida útil indefinida que soportan la evaluación de vida útil indefinida
C16: Información a revelar sobre activos intangibles significativos para la entidad [bloque de texto]
C17: Descripción de los activos intangibles de importancia relativa para la entidad
C18: Activos intangibles materiales (con importancia relativa) para la entidad
C19: Periodo de amortización restante de activos intangibles significativos para la entidad
C20: Activos intangibles adquiridos mediante subvenciones del gobierno
C21: Explicación de activos adquiridos mediante una subvención del gobierno y reconocidos inicialmente por su valor razonable
C22: Activos intangibles cuya titularidad está restringida
C23: Descripción de los activos intangibles totalmente amortizados
... C27: Información a revelar sobre la conciliación de cambios en activos intangibles y plusvalía [bloque de texto]

Sheet Hoja20
B2: Indice
B3: Archivo: | C3: I:\Proyectos2025\proyecto_niif\_backup_legacy\Grupo1_Individual_Directo_ID20037_2024-12-31.xbrl
B4: Empresa: | C4: 20037
B5: Vista: | C5: [823180a] Notas - Activos intangibles - Conciliación incluye plusvalía
B6: Eje X: | C6: N/A
B7: Eje Y: | C7: N/A
B8: Eje Z: | C8: Periodo Actual
F10: Activos [miembro]
F11: Activos intangibles distintos a la plusvalía y plusvalía [miembro] | P11: Métodos de generación [miembro]
F12: Activos intangibles distintos de la plusvalía [miembro] | N12: Plusvalía [miembro] | P12: Generados internamente [miembro] | Q12: No generados internamente [miembro]
F13: Marcas comerciales [miembro] | G13: Activos intangibles de exploración y evaluación [miembro] | H13: Programas de computador [miembro] | I13: Valor de negocio adquirido [miembro] | J13: Desembolsos de desarrollo capitalizados [miembro] | K13: Activos intangibles en desarrollo [miembro] | L13: Otros activos intangibles [miembro]
B14: Información a revelar sobre la conciliación de cambios en activos intangibles y plusvalía [partidas de los estados financieros]
C15: Conciliación de los cambios en activos intangibles y plusvalía [resumen]
D16: Activos intangibles y plusvalía al comienzo del periodo
D17: Cambios en activos intangibles y plusvalía [resumen]
E18: Amortización, activos intangibles distintos de la plusvalía
E19: Pérdida por deterioro de valor reconocida en el resultado del periodo, activos intangibles y plusvalía
E20: Reversión de pérdidas por deterioro de valor reconocidas en el resultado del periodo, activos intangibles distintos de la plusvalía
E21: Incrementos (disminuciones) de revaluaciones, activos intangibles distintos de la plusvalía
E22: Pérdidas por deterioro de valor reconocidas en otro resultado integral, activos intangibles distintos de la plusvalía
E23: Reversión de pérdidas por deterioro de valor reconocidas en otro resultado integral, activos intangibles distintos de la plusvalía
E24: Incrementos (disminuciones) por transferencias y otros cambios, activos intangibles y plusvalía
E25: Disposiciones y retiros de servicio, activos intangibles y plusvalía
E26: Disminuciones por clasificar como mantenidos para la venta, activos intangibles y plusvalía
E27: Disminución por la pérdida de control de una subsidiaria, activos intangibles y plusvalía
E28: Reconocimiento posterior de activos por impuestos diferidos, plusvalía
E29: Total incrementos (disminuciones) de activos intangibles y plusvalía | F29: =-F18-F19+F20+F21-F22+F23+F24-SUM(F25:F28) | G29: =-G18-G19+G20+G21-G22+G23+G24-SUM(G25:G28) | H29: =-H18-H19+H20+H21-H22+H23+H24-SUM(H25:H28) | I29: =-I18-I19+I20+I21-I22+I23+I24-SUM(I25:I28) | J29: =-J18-J19+J20+J21-J22+J23+J24-SUM(J25:J28) | K29: =-K18-K19+K20+K21-K22+K23+K24-SUM(K25:K28) | L29: =-L18-L19+L20+L21-L22+L23+L24-SUM(L25:L28) | M29: =-M18-M19+M20+M21-M22+M23+M24-SUM(M25:M28) | ... Q29: =-Q18-Q19+Q20+Q21-Q22+Q23+Q24-SUM(Q25:Q28)
D30: Activos intangibles y plusvalía al final del periodo
C31: Revaluación de activos intangibles [resumen]
D32: Activos intangibles distintos de la plusvalía, activos revaluados
D33: Activos intangibles distintos de la plusvalía, activos revaluados, al costo
D34: Activos intangibles distintos de la plusvalía, superávit de revaluación

Sheet Hoja21
B2: Indice
B3: Archivo: | C3: I:\Proyectos2025\proyecto_niif\_backup_legacy\Grupo1_Individual_Directo_ID20037_2024-12-31.xbrl
B4: Empresa: | C4: 20037
B5: Vista: | C5: [825100] Notas - Propiedades de inversión - Información descriptiva
B6: Eje X: | C6: N/A
B7: Eje Y: | C7: N/A
B8: Eje Z: | C8: N/A
D10: Periodo Actual
B11: Información a revelar sobre propiedades de inversión [bloque de texto]
C12: Explicación de si la entidad aplicaba el modelo del valor razonable o el modelo del costo para medir las propiedades de inversión
C13: Descripción de los criterios utilizados para distinguir entre propiedades de inversión de las propiedades ocupadas por el propietario y de las propiedades mantenidas para la venta en el curso ordinario del negocio
C14: Descripción de la medida en que el valor razonable de las propiedades de inversión se basan en la valoración por un tasador independiente
C15: Ingreso por alquileres de propiedades de inversión, neto de gastos de operación directos
C16: Cambio acumulado en el valor razonable reconocido en el resultado del periodo por la venta de propiedades de inversión entre conjuntos de activos medidos usando diferentes modelos
C17: Explicación de las restricciones sobre la realización de las propiedades de inversión o remisión de los ingresos y recursos obtenidos por su disposición
C18: Restricciones sobre la realización de propiedades de inversión o la remisión de ingresos e importes obtenidos por su disposición
C19: Explicación de obligaciones contractuales para adquisición, construcción o desarrollo de propiedades de inversión o por reparaciones, mantenimiento o mejoras
C20: Información a revelar sobre ajustes significativos a la valoración obtenida [bloque de texto]
C21: Descripción de propiedades de inversión, al costo o de acuerdo con la NIIF 16 dentro del modelo de valor razonable
C22: Explicación de por qué el valor razonable no puede medirse con fiabilidad para propiedades de inversión, al costo o de acuerdo con la NIIF 16 dentro del modelo del valor razonable
C23: Rango de estimaciones dentro del cual es probable que quede el valor razonable para propiedades de inversión, al costo o de acuerdo con la NIIF 16 dentro del modelo del valor razonable
... C30: Rango de estimaciones dentro de las que es probable que se encuentre el valor razonable para propiedades de inversión, modelo del costo

Sheet Hoja22
B2: Indice
B3: Archivo: | C3: I:\Proyectos2025\proyecto_niif\_backup_legacy\Grupo1_Individual_Directo_ID20037_2024-12-31.xbrl
B4: Empresa: | C4: 20037
B5: Vista: | C5: [825100a] Notas - Propiedades de inversión - Información detallada
B6: Eje X: | C6: N/A
B7: Eje Y: | C7: N/A
B8: Eje Z: | C8: Periodo Actual
F10: Suma de mediciones [miembro]
F11: Al costo [miembro] | G11: Modelo del valor razonable [miembro]
G12: A valor razonable [miembro] | H12: Al costo o de acuerdo con la NIIF 16 dentro del modelo de valor razonable [miembro]
B13: Información a revelar detallada sobre propiedades de inversión [partidas]
C14: Propiedades de inversión al comienzo del periodo | J14: =Hoja2!Q152
C15: Cambios en propiedades de inversión [resumen]
D16: Incrementos, propiedades de inversión [resumen]
E17: Incrementos derivados de desembolsos posteriores reconocidos como activos, propiedades de inversión
E18: Adiciones derivados de adquisiciones, propiedades de inversión
E19: Total adiciones distintas de las de por combinaciones de negocios, propiedades de inversión | F19: =F17+F18 | G19: =G17+G18 | H19: =H17+H18 | I19: =I17+I18 | J19: =J17+J18
D20: Adquisiciones realizadas mediante combinaciones de negocios, propiedades de inversión
D21: Incremento (disminución) por diferencias de cambio netas, propiedades de inversión
D22: Depreciación, propiedades de inversión
D23: Pérdidas por deterioro de valor reconocida en resultados, propiedades de inversión
D24: Reversión de deterioro de valor reconocida en resultados, propiedades de inversión
D25: Ganancias (pérdidas) por ajustes del valor razonable, propiedades de inversión
D26: Transferencias de (a) inventarios y bienes inmuebles ocupados por el propietario, propiedades de inversión
D27: Disposiciones, propiedades de inversión
D28: Disminuciones mediante la clasificación de mantenidos para la venta, propiedades de inversión
D29: Incremento (disminución) por otros cambios, propiedades de inversión
D30: Total incremento (disminución) en propiedades de inversión | F30: =SUM(F19:F21)-F22-F23+SUM(F24:F26)-F27-F28+F29 | G30: =SUM(G19:G21)-G22-G23+SUM(G24:G26)-G27-G28+G29 | H30: =SUM(H19:H21)-H22-H23+SUM(H24:H26)-H27-H28+H29 | I30: =SUM(I19:I21)-I22-I23+SUM(I24:I26)-I27-I28+I29 | J30: =SUM(J19:J21)-J22-J23+SUM(J24:J26)-J27-J28+J29
C31: Propiedades de inversión al final del periodo | J31: =Hoja2!Q41

Sheet Hoja23
B2: Indice
B3: Archivo: | C3: I:\Proyectos2025\proyecto_niif\_backup_legacy\Grupo1_Individual_Directo_ID20037_2024-12-31.xbrl
B4: Empresa: | C4: 20037
B5: Vista: | C5: [825701] Notas - Información a revelar detallada sobre partes relacionadas
B6: Eje X: | C6: N/A
B7: Eje Y: | C7: N/A
B8: Eje Z: | C8: Periodo Actual
C10: Detalle de la parte relacionada [Resumen]
C11: Tipo de parte relacionada | D11: Nombre de la parte relacionada | E11: NIT de la parte relacionada | F11: ID de Prestador de la parte relacionada (Si está vigilado por la Superservicios) | G11: Ciudad de domicilio de la parte relacionada | H11: País donde está constituida la parte relacionada | I11: Porcentaje de participación en la parte relacionada | J11: Participación en parte relacionada | K11: Porcentaje de derechos de voto mantenidos por las participaciones no controladoras | L11: Porcentaje de derechos de voto mantenidos en la parte relacionada | M11: Ganancia (pérdida), atribuible a participaciones no controladoras | N11: Inversiones contabilizadas utilizando el método de la participación de la parte relacionada | O11: Inversiones contabilizadas utilizando el modelo del costo | P11: Inversiones contabilizadas utilizando el modelo del valor razonable | Q11: Nombre Controladora última del Grupo | R11: ID Controladora última del Grupo | S11: Nombre Controladora que emite Estados Financieros Consolidados disponible para uso público | T11: Saldos pendientes de transacciones con partes relacionadas: Importe de las Cuentas por cobrar con partes relacionadas | U11: Saldos pendientes de transacciones con partes relacionadas: Importe de las Cuentas por pagar con partes relacionadas | V11: Importe de los Ingresos con partes relacionadas | W11: Importe de Otros ingresos con partes relacionadas | X11: Importe de los Costos y Gastos con partes relacionadas | Y11: Los costos y gastos reconocido durante el periodo con respecto a las deudas incobrables y de dudoso cobro, procedentes de partes relacionadas | Z11: Importe de los servicios recibidos, transacciones con partes relacionadas | AA11: Descripción de los servicios recibidos, transacciones con partes relacionadas | AB11: Importe de compras de bienes muebles e inmuebles y otros activos, transacciones con partes relacionadas | AC11: Importe de ventas de bienes muebles e inmuebles y otros activos, transacciones con partes relacionadas | AD11: Descripción de las Compras y/o ventas de bienes muebles, inmuebles y otros activos con partes relacionadas | AE11: Información a revelar sobre esta parte relacionada | AF11: Descripción de las políticas contables aplicadas a esta parte relacionada | AG11: ¿La inversión en esta parte relacionada es significativa? | AH11: Activo corriente | AI11: Activo no corriente | AJ11: Activo total | AK11: Pasivo corriente | AL11: Pasivo no corriente | AM11: Pasivo total | AN11: Resultado Integral total
B12: # Fila de parte relacionada

Sheet Hoja24
B2: Indice
B3: Archivo: | C3: I:\Proyectos2025\proyecto_niif\_backup_legacy\Grupo1_Individual_Directo_ID20037_2024-12-31.xbrl
B4: Empresa: | C4: 20037
B5: Vista: | C5: [826380] Notas - Inventarios
B6: Eje X: | C6: N/A
B7: Eje Y: | C7: N/A
B8: Eje Z: | C8: N/A
D10: Periodo Actual
B11: Información a revelar sobre inventarios [bloque de texto]
C12: Descripción de las políticas contables para la medición de inventarios [bloque de texto]
C13: Descripción de las fórmulas del costo de inventario
C14: Inventarios al valor razonable menos los costos de venta
C15: Inventarios, a valor neto realizable
C16: Rebaja del valor del inventario
C17: Reversión de la rebaja del inventario
C18: Descripción de las circunstancias que conducen a reversiones de rebajas de inventarios
C19: Costo de inventarios reconocidos como gasto durante el periodo
C20: Inventarios pignorados como garantía de pasivos

Sheet Hoja25
B2: Indice
B3: Archivo: | C3: I:\Proyectos2025\proyecto_niif\_backup_legacy\Grupo1_Individual_Directo_ID20037_2024-12-31.xbrl
B4: Empresa: | C4: 20037
B5: Vista: | C5: [827570] Notas - Otras provisiones, pasivos contingentes y activos contingentes - Información a revelar
B6: Eje X: | C6: N/A
B7: Eje Y: | C7: N/A
B8: Eje Z: | C8: N/A
D10: Periodo Actual
B11: Información a revelar sobre otras provisiones, pasivos contingentes y activos contingentes [bloque de texto]
