Workbook
Name sspdtipos_TipoNaturalezaEEFF414IndSep: Lists!$B$3:$B$4
Name sspdtipos_TipoGradoRedondeo: Lists!$D$3:$D$6
Name sspdtipos_TipoSiNo: Lists!$F$3:$F$4
Name sspdtipos_TipoPeriodoDeReexpresion: Lists!$H$3:$H$5
Name sspdtipos_TipoIdentificacionResponsablesInformacion: Lists!$J$3:$J$5
Name sspdtipos_TipoDeDictamenDeAuditoria: Lists!$L$3:$L$10
Name sspdtipos_TipoClasificacionEmpresarialSegunResolucionCRA906Del2019: Lists!$N$3:$N$6
Name sspdtipos_TipoPeriodoFaseDeProgresividad: Lists!$P$3:$P$15

Sheet Indice
B2: Tabla de contenidos
B3: [110000] Información general sobre estados financieros
B4: [210000] Estado de situación financiera
B5: [310000] Estado de resultados
B6: [420000] Estado del resultado Integral, Componentes otro resultado integral, Antes de impuestos, individual
B7: [510000] Estado de flujos de efectivo, método directo, individual
B8: [610000] Estado de cambios en el patrimonio
B9: [800100] Notas - Subclasificaciones de activos, pasivos y patrimonios
B10: [800200] Notas - Análisis de ingresos y gastos
B11: [800500] Notas - Lista de Notas
B12: [800600] Notas - Lista de Políticas
B13: [810000] Notas - Información de la entidad y declaración de cumplimiento con el marco normativo
... B43: [900110] FC60 - Porcentaje de provisión de la tarifa de aprovechamiento

Sheet Hoja1
B2: Indice
B3: Archivo: | C3: I:\Proyectos2025\proyecto_niif\_backup_legacy\R414\R414Ind_ID20037_2024-12-31.xbrl
B4: Empresa: | C4: 20037
B5: Vista: | C5: [110000] Información general sobre estados financieros
B6: Eje X: | C6: N/A
B7: Eje Y: | C7: N/A
B8: Eje Z: | C8: N/A
E10: Periodo Actual
B11: Información a revelar sobre información general sobre los estados financieros [bloque de texto]
C12: Nombre de la entidad que informa u otras formas de identificación
C13: Identificación de la Empresa (ID RUPS)
C14: NIT
C15: Descripción de la naturaleza de los estados financieros
C16: Información a revelar sobre la naturaleza del negocio
C17: Fecha de inicio de operaciones (o fecha de constitución si no ha iniciado la prestación de servicios)
C18: Fecha de cierre del periodo sobre el que se informa
C19: Grado de redondeo utilizado en los estados financieros
C20: Detalle sobre este Informe
D21: ¿Estos estados financieros presentan información reexpresada?
D22: Periodo para el cual se presenta información reexpresada

Sheet Lists
B3: 1. Individual | D3: 1 - Pesos | F3: 1. Si | H3: 1. Reexpresión del patrimonio al inicio del periodo actual (Del patrimonio del periodo anterior) | J3: 01 - CÉDULA DE CIUDADANÍA | L3: NAGAS - 1. Limpio | N3: 1 - Grandes Prestadores | P3: 2018
B4: 2. Separado | D4: 2 - Miles de pesos | F4: 2. No | H4: 2. Reexpresión del patrimonio al inicio del periodo anterior (Del patrimonio de dos periodos atrás) | J4: 02 - CÉDULA DE EXTRANJERÍA | L4: NAGAS - 2. Con salvedad | N4: 2 - Pequeños Prestadores | P4: 2019
D5: 3 - Millones de pesos | H5: 3. Reexpresión del patrimonio al inicio de los periodos actual y anterior (Del patrimonio del periodo anterior y de dos periodos atrás) | J5: 03 - PASAPORTE | L5: NAGAS - 3. Negativo | N5: 3 - Prestadores Rurales | P5: 2020
D6: 4 - Pesos redondeada a miles | L6: NAGAS - 4. Abstención de opinión | N6: 4 - Esquema Diferencial | P6: 2021
L7: NIAS - 1. No modificada | P7: 2022
L8: NIAS - 2. Modificada; opinión con salvedades | P8: 2023
L9: NIAS - 3. Modificada; opinión desfavorable o adversa | P9: 2024
L10: NIAS - 4. Modificada; denegación o abstención de opinión | P10: 2025
P11: 2026
P12: 2027
P13: 2028
P14: 2029
P15: 2030

Sheet Hoja2
B2: Indice
B3: Archivo: | C3: I:\Proyectos2025\proyecto_niif\_backup_legacy\R414\R414Ind_ID20037_2024-12-31.xbrl
B4: Empresa: | C4: 20037
B5: Vista: | C5: [210000] Estado de situación financiera
B6: Eje X: | C6: N/A
B7: Eje Y: | C7: N/A
B9: Eje Z: | C9: Periodo Actual
I10: Total ESF por servicios
I11: Acueducto [miembro] | J11: Alcantarillado [miembro] | K11: Aseo [miembro] | L11: Energía Eléctrica [miembro] | M11: Gas combustible por redes [miembro] | N11: Gas Licuado de Petróleo [miembro] | O11: Otras actividades no vigiladas por la SSPD [miembro]
B12: Estado de situación financiera por servicio [partidas]
C13: Activos [resumen]
D14: Activos corrientes [resumen]
E15: Efectivo y equivalentes al efectivo | P15: =Hoja7!F53+Hoja7!F58+Hoja7!F59
F16: Efectivo y equivalentes al efectivo de uso restringido corriente
E17: Cuentas comerciales por cobrar y otras cuentas por cobrar corrientes [Resumen]
F18: Cuentas comerciales por cobrar por prestación de servicios públicos corrientes [Resumen]
G19: Cuentas comerciales por cobrar corrientes por prestación de servicios públicos corrientes (Sin incluir subsidios ni actividades de aprovechamiento)
G20: Cuentas comerciales por cobrar por subsidios corrientes
H21: Cuentas comerciales por cobrar corrientes del servicio público al Ministerio de Minas por concepto de subsidios
G22: Cuentas comerciales por cobrar por actividad de aprovechamiento corrientes
G23: Total cuentas comerciales por cobrar por prestación de servicios públicos corrientes | I23: =I19+I20 | J23: =J19+J20 | K23: =K19+K20+K22 | L23: =L19+L20 | M23: =M19+M20 | N23: =N19+N20 | P23: =P19+P20+P22
F24: Cuentas comerciales por cobrar por venta de bienes corrientes
F25: Cuentas por cobrar corrientes a partes relacionadas
F26: Otras cuentas por cobrar corrientes
F27: Total cuentas comerciales por cobrar y otras cuentas por cobrar corrientes | I27: =SUM(I23:I26) | J27: =SUM(J23:J26) | K27: =SUM(K23:K26) | L27: =SUM(L23:L26) | M27: =SUM(M23:M26) | N27: =SUM(N23:N26) | O27: =SUM(O23:O26) | P27: =SUM(P23:P26)
E28: Inventarios corrientes
E29: Activo por impuesto a las ganancias corriente
E30: Otros activos financieros corrientes
E31: Otros activos no financieros corrientes
E32: Activos corrientes totales | I32: =I15+SUM(I27:I31) | J32: =J15+SUM(J27:J31) | K32: =K15+SUM(K27:K31) | L32: =L15+SUM(L27:L31) | M32: =M15+SUM(M27:M31) | N32: =N15+SUM(N27:N31) | O32: =O15+SUM(O27:O31) | P32: =P15+SUM(P27:P31)
D33: Activos no corrientes [resumen]
E34: Propiedades, planta y equipo | P34: =Hoja7!F31-Hoja7!F32-Hoja7!F33
E35: Efectivo y equivalentes al efectivo - Efectivo de uso restringido
E36: Inversiones en controladas, negocios conjuntos y asociadas [resumen]
F37: Inversiones en asociadas
F38: Inversiones en negocios conjuntos
F39: Inversiones en controladas
F40: Total de Inversiones en controladas, negocios conjuntos y asociadas | I40: =SUM(I37:I39) | J40: =SUM(J37:J39) | K40: =SUM(K37:K39) | L40: =SUM(L37:L39) | M40: =SUM(M37:M39) | N40: =SUM(N37:N39) | O40: =SUM(O37:O39) | P40: =SUM(P37:P39)
E41: Cuentas comerciales por cobrar y otras cuentas por cobrar no corrientes [Resumen]
F42: Cuentas comerciales por cobrar por prestación de servicios públicos no corrientes [Resumen]
...

Sheet Hoja3
B2: Indice
B3: Archivo: | C3: I:\Proyectos2025\proyecto_niif\_backup_legacy\R414\R414Ind_ID20037_2024-12-31.xbrl
B4: Empresa: | C4: 20037
B5: Vista: | C5: [310000] Estado de resultados
B6: Eje X: | C6: N/A
B7: Eje Y: | C7: N/A
B9: Eje Z: | C9: Periodo Actual
E10: Total ER por servicios
E11: Acueducto [miembro] | F11: Alcantarillado [miembro] | G11: Aseo [miembro] | H11: Energía Eléctrica [miembro] | I11: Gas combustible por redes [miembro] | J11: Gas Licuado de Petróleo [miembro] | K11: Otras actividades no vigiladas por la SSPD [miembro]
B12: Estado de resultados por servicio [partidas]
C13: Ganancia (pérdida) [resumen]
D14: Ingresos de actividades ordinarias
D15: Costo de ventas
D16: Ganancia bruta | E16: =-E15+E14 | F16: =-F15+F14 | G16: =-G15+G14 | H16: =-H15+H14 | I16: =-I15+I14 | J16: =-J15+J14 | K16: =-K15+K14 | L16: =-L15+L14
D17: Otros ingresos
D18: Gastos de administración, operación y ventas
D19: Ingresos financieros
D20: Costos financieros
D21: Perdida por aplicación del método de participación patrimonial
D22: Otros gastos
D23: Otras ganancias (pérdidas)
D24: Ganancia (pérdida), antes de impuestos | E24: =E16+E17-E18+E19-SUM(E20:E22)+E23 | F24: =F16+F17-F18+F19-SUM(F20:F22)+F23 | G24: =G16+G17-G18+G19-SUM(G20:G22)+G23 | H24: =H16+H17-H18+H19-SUM(H20:H22)+H23 | I24: =I16+I17-I18+I19-SUM(I20:I22)+I23 | J24: =J16+J17-J18+J19-SUM(J20:J22)+J23 | K24: =K16+K17-K18+K19-SUM(K20:K22)+K23 | L24: =L16+L17-L18+L19-SUM(L20:L22)+L23
D25: Gasto / Ingreso impuesto a las ganancias corriente
D26: Gasto / Ingreso impuesto a las ganancias diferido
D27: Ganancia (pérdida) | E27: =E24-E25-E26 | F27: =F24-F25-F26 | G27: =G24-G25-G26 | H27: =H24-H25-H26 | I27: =I24-I25-I26 | J27: =J24-J25-J26 | K27: =K24-K25-K26 | L27: =L24-L25-L26
B29: Eje Z: | C29: Periodo Anterior
E30: Total ER por servicios
E31: Acueducto [miembro] | F31: Alcantarillado [miembro] | G31: Aseo [miembro] | H31: Energía Eléctrica [miembro] | I31: Gas combustible por redes [miembro] | J31: Gas Licuado de Petróleo [miembro] | K31: Otras actividades no vigiladas por la SSPD [miembro]
B32: Estado de resultados por servicio [partidas]
C33: Ganancia (pérdida) [resumen]
D34: Ingresos de actividades ordinarias
D35: Costo de ventas
D36: Ganancia bruta | E36: =-E35+E34 | F36: =-F35+F34 | G36: =-G35+G34 | H36: =-H35+H34 | I36: =-I35+I34 | J36: =-J35+J34 | K36: =-K35+K34 | L36: =-L35+L34
D37: Otros ingresos
D38: Gastos de administración, operación y ventas
D39: Ingresos financieros
D40: Costos financieros
D41: Perdida por aplicación del método de participación patrimonial
D42: Otros gastos
D43: Otras ganancias (pérdidas)
...

Sheet Hoja4
B2: Indice
B3: Archivo: | C3: I:\Proyectos2025\proyecto_niif\_backup_legacy\R414\R414Ind_ID20037_2024-12-31.xbrl
B4: Empresa: | C4: 20037
B5: Vista: | C5: [420000] Estado del resultado Integral, Componentes otro resultado integral, Antes de impuestos, individual
B6: Eje X: | C6: N/A
B7: Eje Y: | C7: N/A
B8: Eje Z: | C8: N/A
G10: Periodo Actual | H10: Periodo Anterior
B11: Resultado de periodo [resumen]
C12: Ganancia (pérdida) | G12: =Hoja3!L24-Hoja3!L25-Hoja3!L26 | H12: =Hoja3!L44-Hoja3!L45-Hoja3!L46
D13: Otro resultado integral [resumen]
E14: Otro Resultado Integral | G14: =G38+G26 | H14: =H38+H26
F15: Ganancias o pérdidas actuariales y el rendimiento de los activos del plan de beneficios
F16: Total otro resultado integral que no se reclasificará al resultado del periodo, antes de impuestos | G16: =G15 | H16: =H15
E17: Componentes de otro resultado integral que se reclasificarán al resultado del periodo, antes de impuestos [resumen]
F18: Ganancias o pérdidas en inversiones de administracion de liquidez a valor razonable con cambios en el otro resultado integral acumuladas
F19: Ganancias o pérdidas por coberturas de flujos de efectivo acumuladas
F20: Ganancias o pérdidas por cobertura de una inversión neta de un negocio en el extranjero acumuladas
F21: Ganancias o pérdidas por conversión de estados financieros acumuladas
F22: Total otro resultado integral que se reclasificará al resultado del periodo, antes de impuestos | G22: =SUM(G18:G21) | H22: =SUM(H18:H21)
E23: Ganancias o pérdidas por la aplicación del método de participación patrimonial de inversiones en controladas acumuladas
E24: Ganancias o pérdidas por la aplicación del método de participación patrimonial de inversiones en asociadas acumuladas
E25: Ganancias o pérdidas por la aplicación del método de participación patrimonial de inversiones en negocios conjuntos acumuladas
D26: Resultado integral total, antes de impuestos | G26: =G16+SUM(G22:G25) | H26: =H16+SUM(H22:H25)
E27: Impuestos a las ganancias relativos a componentes de otro resultado integral que no se reclasificará al resultado del periodo [resumen]
F28: Impuestos a las ganancias relativos a ganancias (pérdidas) actuariales y el rendimiento de los activos del plan de beneficios
F29: Total impuestos a las ganancias relativos a componentes de otro resultado integral que no se reclasificará al resultado del periodo | G29: =G28 | H29: =H28
D30: Impuestos a las ganancias relativos a componentes de otro resultado integral que se reclasificará al resultado del periodo [resumen]
E31: Impuestos a las ganancias relativos a Ganancias o pérdidas en inversiones de administracion de liquidez a valor razonable con cambios en el otro resultado integral acumuladas
E32: Impuestos a las ganancias relativos a Ganancias o pérdidas por coberturas de flujos de efectivo acumuladas
E33: Ganancias o pérdidas por cobertura de una inversión neta de un negocio Impuestos a las ganancias relativos a en el extranjero acumuladas
E34: Impuestos a las ganancias relativos a Ganancias o pérdidas por conversión de estados financieros acumuladas
E35: Total impuestos a las ganancias relativos a componentes de otro resultado integral que se reclasificará al resultado del periodo | G35: =SUM(G31:G34) | H35: =SUM(H31:H34)
D36: Impuestos a las ganancias relativo a Ganancias o pérdidas por la aplicación del método de participación patrimonial de inversiones en controladas acumuladas
D37: Impuestos a las ganancias relativo a Ganancias o pérdidas por la aplicación del método de participación patrimonial de inversiones en asociadas acumuladas
D38: Total impuestos | G38: =G29+SUM(G35:G37) | H38: =H29+SUM(H35:H37)
D39: Otro Resultado Integral | G39: =G38+G26 | H39: =H38+H26
C40: Resultado integral total | G40: =G14+G12 | H40: =H14+H12

Sheet Hoja5
B2: Indice
B3: Archivo: | C3: I:\Proyectos2025\proyecto_niif\_backup_legacy\R414\R414Ind_ID20037_2024-12-31.xbrl
B4: Empresa: | C4: 20037
B5: Vista: | C5: [510000] Estado de flujos de efectivo, método directo, individual
B6: Eje X: | C6: N/A
B7: Eje Y: | C7: N/A
B9: Eje Z: | C9: Periodo Actual
F10: Total EFE
F11: Acueducto [miembro] | G11: Alcantarillado [miembro] | H11: Aseo [miembro] | I11: Energía Eléctrica [miembro] | J11: Gas combustible por redes [miembro] | K11: Gas Licuado de Petróleo [miembro] | L11: Otras actividades no vigiladas por la SSPD [miembro]
B12: Estado de Flujo de Efectivo por Servicio [partidas]
C13: Flujos de efectivo procedentes de (utilizados en) actividades de operación [resumen]
D14: Clases de cobros por actividades de operación [resumen]
E15: Cobros procedentes de las ventas de bienes y prestación de servicios
E16: Cobros procedentes de regalías, cuotas, comisiones y otros ingresos de actividades ordinarias
E17: Cobros derivados de contratos mantenidos para intermediación o para negociar con ellos
E18: Cobros procedentes de primas y prestaciones, anualidades y otros beneficios de pólizas suscritas
E19: Cobros por rentas y ventas posteriores de activos mantenidos para arrendar a terceros y posteriormente mantenidos para la venta
E20: Otros cobros por actividades de operación
D21: Clases de pagos en efectivo procedentes de actividades de operación [resumen]
E22: Pagos a proveedores por el suministro de bienes y servicios
E23: Pagos procedentes de contratos mantenidos para intermediación o para negociar
E24: Pagos a y por cuenta de los empleados
E25: Pagos por primas y prestaciones, anualidades y otras obligaciones derivadas de las pólizas suscritas
E26: Pagos por producir o adquirir activos mantenidos para arrendar a terceros y posteriormente mantenidos para la venta
E27: Pagos y devoluciones de impuestos sobre las ganancias (a menos que puedan clasificarse específicamente dentro de las actividades de inversión o financiación)
E28: Otros pagos por actividades de operación
D29: Flujos de efectivo netos procedentes (utilizados en) operaciones. | F29: =SUM(F15:F20)-SUM(F22:F28) | G29: =SUM(G15:G20)-SUM(G22:G28) | H29: =SUM(H15:H20)-SUM(H22:H28) | I29: =SUM(I15:I20)-SUM(I22:I28) | J29: =SUM(J15:J20)-SUM(J22:J28) | K29: =SUM(K15:K20)-SUM(K22:K28) | L29: =SUM(L15:L20)-SUM(L22:L28) | M29: =SUM(M15:M20)-SUM(M22:M28)
D30: Otros dividendos pagados
D31: Dividendos recibidos (solo para empresas financieras)
D32: Intereses pagados (solo para empresas financieras)
D33: Intereses recibidos (solo para empresas financieras)
D34: Impuestos a las ganancias reembolsados (pagados)
D35: Otras entradas (salidas) de efectivo, actividades de operación
D36: Flujos de efectivo netos procedentes de (utilizados en) actividades de operación | F36: =-F32+F29-F34-F30+F33+F31+F35 | G36: =-G32+G29-G34-G30+G33+G31+G35 | H36: =-H32+H29-H34-H30+H33+H31+H35 | I36: =-I32+I29-I34-I30+I33+I31+I35 | J36: =-J32+J29-J34-J30+J33+J31+J35 | K36: =-K32+K29-K34-K30+K33+K31+K35 | L36: =-L32+L29-L34-L30+L33+L31+L35 | M36: =-M32+M29-M34-M30+M33+M31+M35
C37: Flujos de efectivo procedentes de (utilizados en) actividades de inversión [resumen]
D38: Flujos de efectivo procedentes de la pérdida de control de subsidiarias u otros negocios
D39: Flujos de efectivo utilizados para obtener el control de subsidiarias u otros negocios
D40: Otros cobros por la venta y reembolsos de patrimonio o instrumentos de deuda de otras entidades
D41: Pagos por la adquisición de instrumentos de pasivo o patrimonio, emitidos por otras entidades
D42: Otros cobros por la venta de participaciones en negocios conjuntos
...

Sheet Hoja6
B2: Indice
B3: Archivo: | C3: I:\Proyectos2025\proyecto_niif\_backup_legacy\R414\R414Ind_ID20037_2024-12-31.xbrl
B4: Empresa: | C4: 20037
B5: Vista: | C5: [610000] Estado de cambios en el patrimonio
B6: Eje X: | C6: N/A
B7: Eje Y: | C7: N/A
B9: Eje Z: | C9: Periodo Actual
F10: Patrimonio [miembro]
F11: Aportes sociales [miembro] | G11: Capital suscrito y pagado [miembro] | H11: Capital fiscal [miembro] | I11: Prima en colocación de acciones cuotas o partes de interés social [miembro] | J11: Reserva Legal [miembro] | K11: Otras reservas [miembro] | L11: Dividendos y participaciones decretadas en especie [miembro] | M11: Ganancias acumuladas[miembro] | N11: Impactos por la transición al nuevo marco de regulación [miembro] | O11: Otras partidas patrimoniales (ORI) [miembro]
O12: Reservas actuariales y el rendimiento de los activos del plan de beneficios [miembro] | P12: Reserva de inversiones de administracion de liquidez a valor razonable con cambios en el otro resultado integral [miembro] | Q12: Reserva por coberturas de flujos de efectivo [miembro] | R12: Reserva por cobertura de una inversión neta de un negocio en el extranjero en el extranjero [miembro] | S12: Reserva por conversión de estados financieros [miembro] | T12: Reserva por la aplicación del método de participación patrimonial de inversiones en controladas [miembro] | U12: Reserva por la aplicación del método de participación patrimonial de inversiones en asociadas [miembro] | V12: Reserva por la aplicación del método de participación patrimonial de inversiones en negocios conjuntos [miembro]
B13: Estado de cambios en el patrimonio [partidas]
C14: Patrimonio al comienzo del periodo | X14: =SUM(Hoja2!P239:P247)+Hoja2!P257
C15: Incremento (disminución) por cambios en políticas contables
C16: Incremento (disminución) por correcciones de errores
C17: Patrimonio al comienzo del periodo incluyendo reexpresión. (Si la hubo)
C18: Cambios en el patrimonio [resumen]
D19: Resultado del ejercicio [resumen]
E20: Ganancia (pérdida) | X20: =Hoja3!L24-Hoja3!L25-Hoja3!L26
E21: Otro Resultado Integral | X21: =Hoja4!G38+Hoja4!G26
E22: Resultado integral total | F22: =F20+F21 | G22: =G20+G21 | H22: =H20+H21 | I22: =I20+I21 | J22: =J20+J21 | K22: =K20+K21 | L22: =L20+L21 | M22: =M20+M21 | ... X22: =X20+X21
D23: Emisión de patrimonio
D24: Dividendos reconocidos como distribuciones a los propietarios
D25: Incrementos (disminuciones) por otros cambios, patrimonio
D26: Total incremento (disminución) en el patrimonio | F26: =F22+F23-F24+F25 | G26: =G22+G23-G24+G25 | H26: =H22+H23-H24+H25 | I26: =I22+I23-I24+I25 | J26: =J22+J23-J24+J25 | K26: =K22+K23-K24+K25 | L26: =L22+L23-L24+L25 | M26: =M22+M23-M24+M25 | ... X26: =X22+X23-X24+X25
C27: Patrimonio al final del periodo | X27: =SUM(Hoja2!P113:P121)+Hoja2!P131
B29: Eje Z: | C29: Periodo Anterior
F30: Patrimonio [miembro]
F31: Aportes sociales [miembro] | G31: Capital suscrito y pagado [miembro] | H31: Capital fiscal [miembro] | I31: Prima en colocación de acciones cuotas o partes de interés social [miembro] | J31: Reserva Legal [miembro] | K31: Otras reservas [miembro] | L31: Dividendos y participaciones decretadas en especie [miembro] | M31: Ganancias acumuladas[miembro] | N31: Impactos por la transición al nuevo marco de regulación [miembro] | O31: Otras partidas patrimoniales (ORI) [miembro]
O32: Reservas actuariales y el rendimiento de los activos del plan de beneficios [miembro] | P32: Reserva de inversiones de administracion de liquidez a valor razonable con cambios en el otro resultado integral [miembro] | Q32: Reserva por coberturas de flujos de efectivo [miembro] | R32: Reserva por cobertura de una inversión neta de un negocio en el extranjero en el extranjero [miembro] | S32: Reserva por conversión de estados financieros [miembro] | T32: Reserva por la aplicación del método de participación patrimonial de inversiones en controladas [miembro] | U32: Reserva por la aplicación del método de participación patrimonial de inversiones en asociadas [miembro] | V32: Reserva por la aplicación del método de participación patrimonial de inversiones en negocios conjuntos [miembro]
B33: Estado de cambios en el patrimonio [partidas]
C34: Patrimonio al comienzo del periodo
C35: Incremento (disminución) por cambios en políticas contables
C36: Incremento (disminución) por correcciones de errores
C37: Patrimonio al comienzo del periodo incluyendo reexpresión. (Si la hubo)
C38: Cambios en el patrimonio [resumen]
D39: Resultado del ejercicio [resumen]
E40: Ganancia (pérdida) | X40: =Hoja3!L44-Hoja3!L45-Hoja3!L46
E41: Otro Resultado Integral | X41: =Hoja4!H38+Hoja4!H26
E42: Resultado integral total | F42: =F40+F41 | G42: =G40+G41 | H42: =H40+H41 | I42: =I40+I41 | J42: =J40+J41 | K42: =K40+K41 | L42: =L40+L41 | M42: =M40+M41 | ... X42: =X40+X41
D43: Emisión de patrimonio
...

Sheet Hoja7
B2: Indice
B3: Archivo: | C3: I:\Proyectos2025\proyecto_niif\_backup_legacy\R414\R414Ind_ID20037_2024-12-31.xbrl
B4: Empresa: | C4: 20037
B5: Vista: | C5: [800100] Notas - Subclasificaciones de activos, pasivos y patrimonios
B6: Eje X: | C6: N/A
B7: Eje Y: | C7: N/A
B8: Eje Z: | C8: N/A
F10: Periodo Actual
B11: Subclasificaciones de activos, pasivos y patrimonios [resumen]
C12: Propiedades, planta y equipo [sinopsis]
D13: Terrenos y construcciones [sinopsis]
E14: Terrenos
E15: Edificios
E16: Total terrenos y edificios | F16: =F14+F15
D17: Maquinaria
D18: Vehículos
D19: Enseres y accesorios
D20: Equipo de oficina
D21: Construcciones en proceso
D22: Propiedades, planta y equipo, información especial [sinopsis]
E23: Vías
E24: Ductos
E25: Plantas
E26: Redes y cables
E27: Relleno sanitario
E28: Activos para generación de energía
E29: Total propiedades, planta y equipo, información especial | F29: =SUM(F23:F28)
D30: Otras propiedades, planta y equipo
D31: Total propiedades, planta y equipo, importe en libros en términos brutos | F31: =SUM(F16:F21)+F29+F30
D32: Depreciación acumulada propiedades, planta y equipo
D33: Deterioro de valor acumulado propiedades, planta y equipo
D34: Total de propiedades, planta y equipo | F34: =F31-F32-F33
C35: Activos intangibles y plusvalía [resumen]
D36: Activos intangibles distintos de la plusvalía [sinopsis]
E37: Marcas comerciales
E38: activos intangibles para exploración y evaluación
E39: Programas de computador
E40: Licencias y franquicias
E41: Derechos de propiedad intelectual, patentes y otros derechos de propiedad industrial, servicio y derechos de explotación
E42: Activos intangibles en desarrollo
...

Sheet Hoja8
B2: Indice
B3: Archivo: | C3: I:\Proyectos2025\proyecto_niif\_backup_legacy\R414\R414Ind_ID20037_2024-12-31.xbrl
B4: Empresa: | C4: 20037
B5: Vista: | C5: [800200] Notas - Análisis de ingresos y gastos
B6: Eje X: | C6: N/A
B7: Eje Y: | C7: N/A
B8: Eje Z: | C8: N/A
E10: Periodo Actual
B11: Clases de gasto de beneficios a los empleados
C12: Beneficios a corto plazo
D13: Sueldos y salarios
C14: Beneficios a largo plazo
D15: Premios o bonificaciones por largo tiempo de servicio
C16: Beneficios por terminación del vínculo laboral o contractual.
D17: Beneficios de Ley
D18: Obligaciones implícitas
D19: Finalización anticipada de contrato
D20: Oferta de beneficios por terminación anticipada
C21: Beneficios posempleo.
D22: Pensiones a cargo de la empresa
D23: Seguros de vida, asistencia médica, cobertura educativa
C24: Total de gastos por beneficios a los empleados | E24: =E21+E12+E14+E16

Sheet Hoja9
B2: Indice
B3: Archivo: | C3: I:\Proyectos2025\proyecto_niif\_backup_legacy\R414\R414Ind_ID20037_2024-12-31.xbrl
B4: Empresa: | C4: 20037
B5: Vista: | C5: [800500] Notas - Lista de Notas
B6: Eje X: | C6: N/A
B7: Eje Y: | C7: N/A
B8: Eje Z: | C8: N/A
E10: Periodo Actual
B11: Información a revelar sobre notas y otra información explicativa [bloque de texto]
C12: Información a revelar sobre juicios y estimaciones contables [bloque de texto]
C13: Información a revelar sobre remuneración de los auditores [bloque de texto]
C14: Información a revelar sobre la autorización de los estados financieros [bloque de texto]
C15: Información a revelar sobre efectivo y equivalentes al efectivo [bloque de texto]
C16: Información a revelar sobre el estado de flujos de efectivo [bloque de texto]
C17: Información a revelar sobre activos contingentes [bloque de texto]
C18: Información a revelar sobre compromisos y pasivos contingentes [bloque de texto]
C19: Información a revelar sobre gastos por depreciación y amortización [bloque de texto]
C20: Información a revelar sobre instrumentos financieros derivados [bloque de texto]
C21: Información a revelar sobre el efecto de las variaciones en las tasas de cambio de la moneda extranjera [bloque de texto]
C22: Información a revelar sobre beneficios a los empleados [bloque de texto]
C23: Información a revelar sobre hechos ocurridos después del periodo sobre el que se informa [bloque de texto]
... C31: Información a revelar sobre subvenciones del gobierno [bloque de texto]
D32: Descripción de la naturaleza y cuantía de las subvenciones reconocidas
D33: Descripción de las condiciones cumplidas, por cumplir y otras contingencias relacionadas con las subvenciones condicionadas que no se hayan reconocido en resultados
D34: Periodos que cubre las subvención, así como los montos amortizados y por amortizar
D35: Descrición de las subvenciones a las que no se les haya podido asignar un valor
D36: Descripción de otro de tipo de ayudas gubernamentales de las cuales se haya beneficiado directamente la empresa
C37: Información a revelar sobre deterioro de valor de activos [bloque de texto]
C38: Información a revelar sobre impuestos a las ganancias [bloque de texto]
C39: Información a revelar sobre empleados [bloque de texto]
C40: Información a revelar sobre personal clave de la gerencia [bloque de texto]
C41: Información a revelar sobre activos intangibles [bloque de texto]
C42: Información a revelar sobre gastos por intereses [bloque de texto]
C43: Información a revelar sobre ingresos por intereses [bloque de texto]
C44: Información a revelar sobre inventarios [bloque de texto]
C45: Información a revelar sobre propiedades de inversión [bloque de texto]
C46: Información a revelar sobre inversiones contabilizadas utilizando el método de la participación [bloque de texto]
C47: Información a revelar sobre inversiones distintas de las contabilizadas utilizando el método de la participación [bloque de texto]
C48: Información a revelar sobre arrendamientos [bloque de texto]
... C67: Información a revelar sobre deudores comerciales y otras cuentas por cobrar [bloque de texto]

Sheet Hoja10
B2: Indice
B3: Archivo: | C3: I:\Proyectos2025\proyecto_niif\_backup_legacy\R414\R414Ind_ID20037_2024-12-31.xbrl
B4: Empresa: | C4: 20037
B5: Vista: | C5: [800600] Notas - Lista de Políticas
B6: Eje X: | C6: N/A
B7: Eje Y: | C7: N/A
B8: Eje Z: | C8: N/A
D10: Periodo Actual
B11: Información a revelar sobre un resumen de las políticas contables significativas [bloque de texto]
C12: Descripción de la política contable de activos financieros disponibles para la venta [bloque de texto]
C13: Descripción de la política contable para costos de financiación [bloque de texto]
C14: Descripción de la política contable para préstamos por pagar [bloque de texto]
C15: Descripción de la política contable para instrumentos financieros derivados [bloque de texto]
C16: Descripción de la política contable para beneficios a los empleados [bloque de texto]
C17: Descripción de la política contable para gastos [bloque de texto]
C18: Descripción de la política contable para conversión de moneda extranjera [bloque de texto]
C19: Descripción de la política contable para la moneda funcional [bloque de texto]
C20: Descripción de la política contable para la plusvalía [bloque de texto]
C21: Descripción de las políticas contables para subvenciones gubernamentales [bloque de texto]
C22: Descripción de la política contable para deterioro del valor de activos [bloque de texto]
C23: Descripción de la política contable para impuestos a las ganancias [bloque de texto]
... C43: Descripción de la política contable para el reconocimiento de ingresos por contratos de construcción [bloque de texto]

Sheet Hoja11
B2: Indice
B3: Archivo: | C3: I:\Proyectos2025\proyecto_niif\_backup_legacy\R414\R414Ind_ID20037_2024-12-31.xbrl
B4: Empresa: | C4: 20037
B5: Vista: | C5: [810000] Notas - Información de la entidad y declaración de cumplimiento con el marco normativo
B6: Eje X: | C6: N/A
B7: Eje Y: | C7: N/A
B8: Eje Z: | C8: N/A
E10: Periodo Actual
B11: Información a revelar sobre notas y otra información explicativa [bloque de texto]
C12: Nombre de la controladora última del grupo
C13: Ciudad donde se encuentra ubicada la sede administrativa
C14: Dirección de la sede administrativa de la entidad
C15: Email institucional
C16: Declaración explícita y sin reservas de cumplimiento del Marco Normativo para Entidades de Gobierno Resolución 414 CGN, el cual hace parte del Régimen de Contabilidad Pública [bloque de texto]
C17: Información a revelar sobre incertidumbres o cambios ordenados que comprometen su continuidad como supresión, fusión, escisión o liquidación
C18: Explicación de porqué no se presume que la actividad se llevara a cabo por tiempo indefinido
C19: Información a revelar sobre finalización de la prestación de los servicios inscritos en RUPS. [Resumen]
D20: Información a revelar sobre incertidumbres sobre la capacidad de dar continuidad a la prestación de uno o más servicios inscritos en RUPS
D21: ¿Durante el periodo sobre el que se informa se finalizó la prestación de uno o más servicios inscritos en RUPS?
D22: Detalle sobre la finalización de la prestación de los servicios inscritos en RUPS. (indicar servicio y fecha de finalización del servicio)
C23: Información a revelar sobre un resumen de las políticas contables significativas [bloque de texto]
D24: Explicación de los criterios de medición utilizados para preparar los estados financieros [bloque de texto]
D25: Descripción de otras políticas contables relevantes para comprender los estados financieros [bloque de texto]
D26: Explicación de supuestos realizados acerca del futuro y otras causas de incertidumbre en las estimaciones realizadas al final del periodo contable, que tengan un riesgo significativo de ocasionar ajustes importantes en el valor en libros de los activos o pasivos dentro del periodo contable siguiente.
C27: Información relacionada con Objetivos de Desarrollo Sostenible impulsadas por la Organización de Naciones Unidas [Abstracto]
D28: La entidad ha implementado programas, prácticas o políticas relacionados con objetivos de desarrollo sostenible?
D29: La entidad prepara reportes de sostenibilidad?
D30: Si lo presenta como reporte a una entidad de supervisión específica, a cuál?
D31: La entidad cuenta con objetivos de desarrollo sostenible para el eje económico?
D32: Mencione que indicadores calcula. Explique los elementos que componen cada indicador.

Sheet Hoja12
B2: Indice
B3: Archivo: | C3: I:\Proyectos2025\proyecto_niif\_backup_legacy\R414\R414Ind_ID20037_2024-12-31.xbrl
B4: Empresa: | C4: 20037
B5: Vista: | C5: [811001] Notas - Políticas contables, cambios en las estimaciones contables y errores
B6: Eje X: | C6: N/A
B7: Eje Y: | C7: N/A
B8: Eje Z: | C8: N/A
C10: Detalle de los cambios en políticas contables, estimaciones contables y errores [Resumen]
C11: Tipo de Cambio por politica, estimación o error | D11: Descripción del cambio en política, estimación o error | E11: Impacto en el activo por cambio por política, estimación o error | F11: Impacto en el pasivo por cambio por política, estimación o error | G11: Impacto en el patrimonio por cambio por política, estimación o error | H11: Impacto en el resultado por cambio por política, estimación o error
B12: # Fila de cambio por política, estimación o error

Sheet Hoja13
B2: Indice
B3: Archivo: | C3: I:\Proyectos2025\proyecto_niif\_backup_legacy\R414\R414Ind_ID20037_2024-12-31.xbrl
B4: Empresa: | C4: 20037
B5: Vista: | C5: [825701] Notas - Información a revelar detallada sobre partes relacionadas
B6: Eje X: | C6: N/A
B7: Eje Y: | C7: N/A
B8: Eje Z: | C8: Periodo Actual
C10: Detalle de la parte relacionada [Resumen]
C11: Tipo de parte relacionada | D11: Nombre de la parte relacionada | E11: NIT de la parte relacionada | F11: ID de Prestador de la parte relacionada (Si está vigilado por la Superservicios) | G11: Ciudad de domicilio de la parte relacionada | H11: País donde está constituida la parte relacionada | I11: Porcentaje de participación en la parte relacionada | J11: Si es asociada y su participación y/o derechos de voto son menores del 20% explique porque hay influencia significativa; si es mayor al 20% y no hay influencia significativa, explique porqué | K11: Valor en libros de la Inversión en parte relacionada | L11: Inversiones contabilizadas utilizando el método de la participación de la parte relacionada | M11: Riesgo asociado con su participación en la parte relacionada | N11: Nombre Controladora última del Grupo | O11: ID Controladora última del Grupo | P11: Nombre Controladora que emite Estados Financieros Consolidados disponible para uso público | Q11: Importe de las Cuentas por Cobrar con la parte relacionada | R11: Importe de las Cuentas por Pagar con la parte relacionada | S11: Importe de los Ingresos con la parte relacionada | T11: Importe de los Costos y Gastos con la parte relacionada | U11: Información a revelar sobre esta parte relacionada
B12: # Fila de parte relacionada

Sheet Hoja14
B2: Indice
B3: Archivo: | C3: I:\Proyectos2025\proyecto_niif\_backup_legacy\R414\R414Ind_ID20037_2024-12-31.xbrl
B4: Empresa: | C4: 20037
B5: Vista: | C5: [835110] Notas - Impuestos a las ganancias
B6: Eje X: | C6: N/A
B7: Eje Y: | C7: N/A
B8: Eje Z: | C8: N/A
F10: Periodo Actual
B11: Información a revelar sobre impuestos a las ganancias [bloque de texto]
C12: Principales componentes del gasto (ingreso) por impuestos [resumen]
D13: Gasto (ingreso) por impuestos corriente y ajustes por impuestos corrientes de periodos anteriores [resumen]
E14: Gasto (ingreso) por impuesto corriente
E15: Ajustes por impuestos corrientes de periodos anteriores
E16: Total gastos (ingresos) por impuestos corrientes y ajustes a impuestos corrientes de periodos anteriores | F16: =F14+F15
D17: Gasto (ingreso) por impuestos diferidos relacionado con el origen y reversión de diferencias temporarias
D18: Gasto (ingreso) por impuestos diferidos relacionado con cambios en las tasas fiscales o con la imposición de nuevos impuestos
D19: Gasto (ingreso) sobre el gasto por impuesto diferido originado por variaciones derivadas de una revisión de las autoridades fiscales
D20: Ajustes sobre el gasto por impuestos diferidos derivados de un cambio en la situación fiscal de la empresa
D21: Otros ajustes realizados, durante el periodo contable, a los activos por impuestos diferidos
D22: Gasto por impuestos relacionado con aplicación retroactiva por efecto de un cambio en política contable y con la reexpresión retroactiva por efecto de una corrección de errores de periodos anteriores
D23: Total de gasto (ingreso) por impuestos | F23: =SUM(F16:F22)

Sheet Hoja15
B2: Indice
B3: Archivo: | C3: I:\Proyectos2025\proyecto_niif\_backup_legacy\R414\R414Ind_ID20037_2024-12-31.xbrl
B4: Empresa: | C4: 20037
B5: Vista: | C5: [900010] Notas - Información a revelar sobre los responsables de la información financiera e información del AEGR
B6: Eje X: | C6: N/A
B7: Eje Y: | C7: N/A
B8: Eje Z: | C8: Periodo Actual
D10: Detalle [resumen]
D11: Nombres | E11: Apellidos | F11: Tipo de documento | G11: Número de documento | H11: Email | I11: Tarjeta profesional | J11: Si la persona natural actua como miembro de una persona jurídica, indique la razón social | K11: Si la persona natural actua como miembro de una persona jurídica, indique el NIT | L11: Tipo de norma de auditoría aplicada y tipo de dictamen
B12: Relación [miembro]
C13: Representante legal [miembro]
C14: Contador [miembro]
C15: Jefe de la oficina de control interno [miembro]
C16: Revisor fiscal [miembro]
C17: AEGR [miembro]

Sheet Hoja16
B2: Indice
B3: Archivo: | C3: I:\Proyectos2025\proyecto_niif\_backup_legacy\R414\R414Ind_ID20037_2024-12-31.xbrl
B4: Empresa: | C4: 20037
B5: Vista: | C5: [900017a] FC01-1 - Gastos de servicios públicos - Acueducto
B6: Eje X: | C6: N/A
B7: Eje Y: | C7: N/A
B8: Eje Z: | C8: Periodo Actual
E10: Acueducto [miembro]
E11: Gasto administrativo - Acueducto [miembro] | F11: Gasto operativo - Acueducto [miembro]
B12: Gastos [resumen]
C13: Beneficios a empleados
C14: Honorarios
C15: Impuestos, Tasas y Contribuciones (No incluye impuesto de renta)
C16: Generales
C17: Deterioro
C18: Depreciación
C19: Amortización
C20: Provisiones [resumen]
D21: Litigios y demandas
D22: Garantías
D23: Diversas
D24: Total gastos de provisiones | E24: =SUM(E21:E23) | F24: =SUM(F21:F23) | G24: =SUM(G21:G23)
C25: Arrendamientos
C26: Otros Gastos [resumen]
D27: Comisiones
D28: Ajuste por diferencia en cambio
D29: Financieros
D30: Pérdidas por aplicación del método de participación patrimonial
D31: Gastos diversos
D32: Donaciones
D33: Total otros gastos | E33: =SUM(E27:E32) | F33: =SUM(F27:F32) | G33: =SUM(G27:G32)
C34: Impuesto a las ganancias corrientes
C35: Impuesto a las ganancias diferido
C36: Bienes y servicios públicos para la venta [resumen]
D37: Compras en bloque y/o a largo plazo
D38: Compras en bolsa y/o a corto plazo
D39: Gastos por suministro de agua potable (agua en bloque)
D40: Gastos de conexión
D41: Uso de Líneas, redes y ductos
D42: Gastos de distribución y/o comercialización de gas combustible por redes
...

Sheet Hoja17
B2: Indice
B3: Archivo: | C3: I:\Proyectos2025\proyecto_niif\_backup_legacy\R414\R414Ind_ID20037_2024-12-31.xbrl
B4: Empresa: | C4: 20037
B5: Vista: | C5: [900017b] FC01-2 - Gastos de servicios públicos - Alcantarillado
B6: Eje X: | C6: N/A
B7: Eje Y: | C7: N/A
B8: Eje Z: | C8: Periodo Actual
E10: Alcantarillado [miembro]
E11: Gasto administrativo - Alcantarillado [miembro] | F11: Gasto operativo - Alcantarillado [miembro]
B12: Gastos [resumen]
C13: Beneficios a empleados
C14: Honorarios
C15: Impuestos, Tasas y Contribuciones (No incluye impuesto de renta)
C16: Generales
C17: Deterioro
C18: Depreciación
C19: Amortización
C20: Provisiones [resumen]
D21: Litigios y demandas
D22: Garantías
D23: Diversas
D24: Total gastos de provisiones | E24: =SUM(E21:E23) | F24: =SUM(F21:F23) | G24: =SUM(G21:G23)
C25: Arrendamientos
C26: Otros Gastos [resumen]
D27: Comisiones
D28: Ajuste por diferencia en cambio
D29: Financieros
D30: Pérdidas por aplicación del método de participación patrimonial
D31: Gastos diversos
D32: Donaciones
D33: Total otros gastos | E33: =SUM(E27:E32) | F33: =SUM(F27:F32) | G33: =SUM(G27:G32)
C34: Impuesto a las ganancias corrientes
C35: Impuesto a las ganancias diferido
C36: Bienes y servicios públicos para la venta [resumen]
D37: Compras en bloque y/o a largo plazo
D38: Compras en bolsa y/o a corto plazo
D39: Gastos por suministro de agua potable (agua en bloque)
D40: Gastos de conexión
D41: Uso de Líneas, redes y ductos
D42: Gastos de distribución y/o comercialización de gas combustible por redes
...

Sheet Hoja18
B2: Indice
B3: Archivo: | C3: I:\Proyectos2025\proyecto_niif\_backup_legacy\R414\R414Ind_ID20037_2024-12-31.xbrl
B4: Empresa: | C4: 20037
B5: Vista: | C5: [900017c] FC01-3 - Gastos de servicios públicos - Aseo
B6: Eje X: | C6: N/A
B7: Eje Y: | C7: N/A
B8: Eje Z: | C8: Periodo Actual
E10: Aseo [miembro]
E11: Gasto administrativo - Aseo [miembro] | F11: Gasto operativo - Aseo [miembro]
B12: Gastos [resumen]
C13: Beneficios a empleados
C14: Honorarios
C15: Impuestos, Tasas y Contribuciones (No incluye impuesto de renta)
C16: Generales
C17: Deterioro
C18: Depreciación
C19: Amortización
C20: Provisiones [resumen]
D21: Litigios y demandas
D22: Garantías
D23: Diversas
D24: Total gastos de provisiones | E24: =SUM(E21:E23) | F24: =SUM(F21:F23) | G24: =SUM(G21:G23)
C25: Arrendamientos
C26: Otros Gastos [resumen]
D27: Comisiones
D28: Ajuste por diferencia en cambio
D29: Financieros
D30: Pérdidas por aplicación del método de participación patrimonial
D31: Gastos diversos
D32: Donaciones
D33: Total otros gastos | E33: =SUM(E27:E32) | F33: =SUM(F27:F32) | G33: =SUM(G27:G32)
C34: Impuesto a las ganancias corrientes
C35: Impuesto a las ganancias diferido
C36: Bienes y servicios públicos para la venta [resumen]
D37: Compras en bloque y/o a largo plazo
D38: Compras en bolsa y/o a corto plazo
D39: Gastos por suministro de agua potable (agua en bloque)
D40: Gastos de conexión
D41: Uso de Líneas, redes y ductos
D42: Gastos de distribución y/o comercialización de gas combustible por redes
...

Sheet Hoja19
B2: Indice
B3: Archivo: | C3: I:\Proyectos2025\proyecto_niif\_backup_legacy\R414\R414Ind_ID20037_2024-12-31.xbrl
B4: Empresa: | C4: 20037
B5: Vista: | C5: [900017d] FC01-4 - Gastos de servicios públicos - Energía
B6: Eje X: | C6: N/A
B7: Eje Y: | C7: N/A
B8: Eje Z: | C8: Periodo Actual
E10: Energía Eléctrica [miembro]
E11: ENERGIA - SIN [miembro] | T11: ENERGIA - ZNI [miembro] | AF11: Gasto administrativo - Energía eléctrica [miembro] | AG11: Gasto operativo - Energía Eléctrica [miembro]
E12: Generación [miembro] | H12: Transmisión [miembro] | K12: Distribución [miembro] | N12: Comercialización [miembro] | Q12: Gasto administrativo - Energía Eléctrica SIN [miembro] | R12: Gasto operativo - Energía Eléctrica SIN [miembro] | T12: Generación [miembro] | W12: Distribución [miembro] | Z12: Comercialización [miembro] | AC12: Gasto administrativo - Energía Eléctrica ZNI [miembro] | AD12: Gasto operativo - Energía Eléctrica ZNI [miembro]
E13: Gasto administrativo - Energía Eléctrica SIN - Generación [miembro] | F13: Gasto operativo - Energía Eléctrica SIN - Generación [miembro] | H13: Gasto administrativo - Energía Eléctrica SIN - Transmisión [miembro] | I13: Gasto operativo - Energía Eléctrica SIN - Transmisión [miembro] | K13: Gasto administrativo - Energía Eléctrica SIN - Distribución [miembro] | L13: Gasto operativo - Energía Eléctrica SIN - Distribución [miembro] | N13: Gasto administrativo - Energía Eléctrica SIN - Comercialización [miembro] | O13: Gasto operativo - Energía Eléctrica SIN - Comercialización [miembro] | T13: Gasto administrativo - Energía Eléctrica ZNI - Generación [miembro] | U13: Gasto operativo - Energía Eléctrica ZNI - Generación [miembro] | W13: Gasto administrativo - Energía Eléctrica ZNI - Distribución [miembro] | X13: Gasto operativo - Energía Eléctrica ZNI - Distribución [miembro] | Z13: Gasto administrativo - Energía Eléctrica ZNI - Comercialización [miembro] | AA13: Gasto operativo - Energía Eléctrica ZNI - Comercialización [miembro]
B14: Gastos [resumen]
C15: Beneficios a empleados
C16: Honorarios
C17: Impuestos, Tasas y Contribuciones (No incluye impuesto de renta)
C18: Generales
C19: Deterioro
C20: Depreciación
C21: Amortización
C22: Provisiones [resumen]
D23: Litigios y demandas
D24: Garantías
D25: Diversas
D26: Total gastos de provisiones | E26: =SUM(E23:E25) | F26: =SUM(F23:F25) | G26: =SUM(G23:G25) | H26: =SUM(H23:H25) | I26: =SUM(I23:I25) | J26: =SUM(J23:J25) | K26: =SUM(K23:K25) | L26: =SUM(L23:L25) | ... AH26: =SUM(AH23:AH25)
C27: Arrendamientos
C28: Otros Gastos [resumen]
D29: Comisiones
D30: Ajuste por diferencia en cambio
D31: Financieros
D32: Pérdidas por aplicación del método de participación patrimonial
D33: Gastos diversos
D34: Donaciones
D35: Total otros gastos | E35: =SUM(E29:E34) | F35: =SUM(F29:F34) | G35: =SUM(G29:G34) | H35: =SUM(H29:H34) | I35: =SUM(I29:I34) | J35: =SUM(J29:J34) | K35: =SUM(K29:K34) | L35: =SUM(L29:L34) | ... AH35: =SUM(AH29:AH34)
C36: Impuesto a las ganancias corrientes
C37: Impuesto a las ganancias diferido
C38: Bienes y servicios públicos para la venta [resumen]
D39: Compras en bloque y/o a largo plazo
D40: Compras en bolsa y/o a corto plazo
D41: Gastos por suministro de agua potable (agua en bloque)
D42: Gastos de conexión
...

Sheet Hoja20
B2: Indice
B3: Archivo: | C3: I:\Proyectos2025\proyecto_niif\_backup_legacy\R414\R414Ind_ID20037_2024-12-31.xbrl
B4: Empresa: | C4: 20037
B5: Vista: | C5: [900017e] FC01-5 - Gastos de servicios públicos - Gas combustible por redes
B6: Eje X: | C6: N/A
B7: Eje Y: | C7: N/A
B8: Eje Z: | C8: Periodo Actual
E10: Gas combustible por redes [miembro]
E11: Producción [miembro] | H11: Transporte [miembro] | K11: Distribución [miembro] | N11: Comercialización [miembro] | Q11: Comercialización de gas importado [miembro] | T11: Regasificación [miembro] | W11: Gasto administrativo - Gas Combustible por redes [miembro] | X11: Gasto operativo - Gas Combustible por redes [miembro]
E12: Gasto administrativo - Gas Combustible por redes - Producción [miembro] | F12: Gasto operativo - Gas Combustible por redes - Producción [miembro] | H12: Gasto administrativo - Gas Combustible por redes - Transporte [miembro] | I12: Gasto operativo - Gas Combustible por redes - Transporte [miembro] | K12: Gasto administrativo - Gas Combustible por redes - Distribución [miembro] | L12: Gasto operativo - Gas Combustible por redes - Distribución [miembro] | N12: Gasto administrativo - Gas Combustible por redes - Comercialización [miembro] | O12: Gasto operativo - Gas Combustible por redes - Comercialización [miembro] | Q12: Gasto administrativo - Gas Combustible por redes - Comercialización de gas importado [miembro] | R12: Gasto operativo - Gas Combustible por redes - Comercialización de gas importado[miembro] | T12: Gasto administrativo - Gas Combustible por redes - Regasificación [miembro] | U12: Gasto operativo - Gas Combustible por redes - Regasificación [miembro]
B13: Gastos [resumen]
C14: Beneficios a empleados
C15: Honorarios
C16: Impuestos, Tasas y Contribuciones (No incluye impuesto de renta)
C17: Generales
C18: Deterioro
C19: Depreciación
C20: Amortización
C21: Provisiones [resumen]
D22: Litigios y demandas
D23: Garantías
D24: Diversas
D25: Total gastos de provisiones | E25: =SUM(E22:E24) | F25: =SUM(F22:F24) | G25: =SUM(G22:G24) | H25: =SUM(H22:H24) | I25: =SUM(I22:I24) | J25: =SUM(J22:J24) | K25: =SUM(K22:K24) | L25: =SUM(L22:L24) | ... Y25: =SUM(Y22:Y24)
C26: Arrendamientos
C27: Otros Gastos [resumen]
D28: Comisiones
D29: Ajuste por diferencia en cambio
D30: Financieros
D31: Pérdidas por aplicación del método de participación patrimonial
D32: Gastos diversos
D33: Donaciones
D34: Total otros gastos | E34: =SUM(E28:E33) | F34: =SUM(F28:F33) | G34: =SUM(G28:G33) | H34: =SUM(H28:H33) | I34: =SUM(I28:I33) | J34: =SUM(J28:J33) | K34: =SUM(K28:K33) | L34: =SUM(L28:L33) | ... Y34: =SUM(Y28:Y33)
C35: Impuesto a las ganancias corrientes
C36: Impuesto a las ganancias diferido
C37: Bienes y servicios públicos para la venta [resumen]
D38: Compras en bloque y/o a largo plazo
D39: Compras en bolsa y/o a corto plazo
D40: Gastos por suministro de agua potable (agua en bloque)
D41: Gastos de conexión
D42: Uso de Líneas, redes y ductos
...

Sheet Hoja21
B2: Indice
B3: Archivo: | C3: I:\Proyectos2025\proyecto_niif\_backup_legacy\R414\R414Ind_ID20037_2024-12-31.xbrl
B4: Empresa: | C4: 20037
B5: Vista: | C5: [900017f] FC01-6 - Gastos de servicios públicos - Gas licuado del petroleo
B6: Eje X: | C6: N/A
B7: Eje Y: | C7: N/A
B8: Eje Z: | C8: Periodo Actual
E10: Gas Licuado de Petróleo [miembro]
E11: Comercialización Mayorista [miembro] | H11: Distribución Inversionista [miembro] | K11: Comercialización Minorista [miembro] | N11: Transporte [miembro] | Q11: Gasto administrativo - GLP [miembro] | R11: Gasto operativo - GLP [miembro]
E12: Gasto administrativo - GLP - Comercialización mayorista [miembro] | F12: Gasto operativo - GLP - Comercialización mayorista [miembro] | H12: Gasto administrativo - GLP - Distribución inversionista [miembro] | I12: Gasto operativo - GLP - Distribución inversionista [miembro] | K12: Gasto administrativo - GLP - Comercialización minorista [miembro] | L12: Gasto operativo - GLP - Comercialización minorista [miembro] | N12: Gasto administrativo - GLP - Transporte [miembro] | O12: Gasto operativo - GLP - Transporte [miembro]
B13: Gastos [resumen]
C14: Beneficios a empleados
C15: Honorarios
C16: Impuestos, Tasas y Contribuciones (No incluye impuesto de renta)
C17: Generales
C18: Deterioro
C19: Depreciación
C20: Amortización
C21: Provisiones [resumen]
D22: Litigios y demandas
D23: Garantías
D24: Diversas
D25: Total gastos de provisiones | E25: =SUM(E22:E24) | F25: =SUM(F22:F24) | G25: =SUM(G22:G24) | H25: =SUM(H22:H24) | I25: =SUM(I22:I24) | J25: =SUM(J22:J24) | K25: =SUM(K22:K24) | L25: =SUM(L22:L24) | ... S25: =SUM(S22:S24)
C26: Arrendamientos
C27: Otros Gastos [resumen]
D28: Comisiones
D29: Ajuste por diferencia en cambio
D30: Financieros
D31: Pérdidas por aplicación del método de participación patrimonial
D32: Gastos diversos
D33: Donaciones
D34: Total otros gastos | E34: =SUM(E28:E33) | F34: =SUM(F28:F33) | G34: =SUM(G28:G33) | H34: =SUM(H28:H33) | I34: =SUM(I28:I33) | J34: =SUM(J28:J33) | K34: =SUM(K28:K33) | L34: =SUM(L28:L33) | ... S34: =SUM(S28:S33)
C35: Impuesto a las ganancias corrientes
C36: Impuesto a las ganancias diferido
C37: Bienes y servicios públicos para la venta [resumen]
D38: Compras en bloque y/o a largo plazo
D39: Compras en bolsa y/o a corto plazo
D40: Gastos por suministro de agua potable (agua en bloque)
D41: Gastos de conexión
D42: Uso de Líneas, redes y ductos
...

Sheet Hoja22
B2: Indice
B3: Archivo: | C3: I:\Proyectos2025\proyecto_niif\_backup_legacy\R414\R414Ind_ID20037_2024-12-31.xbrl
B4: Empresa: | C4: 20037
B5: Vista: | C5: [900017g] FC01-7 - Gastos de servicios públicos - Total servicios públicos
B6: Eje X: | C6: N/A
B7: Eje Y: | C7: N/A
B8: Eje Z: | C8: Periodo Actual
E10: Total Periodo [miembro]
E11: Total prestación servicios públicos nacionales [miembro] | H11: Otras actividades no vigiladas por la SSPD [miembro] | K11: Gasto administrativo - Total del periodo [miembro] | L11: Gasto operativo - Total del periodo [miembro]
E12: Gasto administrativo - Total de servicios públicos [miembro] | F12: Gasto operativo - Total de servicios públicos [miembro] | H12: Gasto administrativo - Otras actividades no vigiladas [miembro] | I12: Gasto operativo - Otras actividades no vigiladas [miembro]
B13: Gastos [resumen]
C14: Beneficios a empleados
C15: Honorarios
C16: Impuestos, Tasas y Contribuciones (No incluye impuesto de renta)
C17: Generales
C18: Deterioro
C19: Depreciación
C20: Amortización
C21: Provisiones [resumen]
D22: Litigios y demandas
D23: Garantías
D24: Diversas
D25: Total gastos de provisiones | E25: =SUM(E22:E24) | F25: =SUM(F22:F24) | G25: =SUM(G22:G24) | H25: =SUM(H22:H24) | I25: =SUM(I22:I24) | J25: =SUM(J22:J24) | K25: =SUM(K22:K24) | L25: =SUM(L22:L24) | M25: =SUM(M22:M24)
C26: Arrendamientos
C27: Otros Gastos [resumen]
D28: Comisiones
D29: Ajuste por diferencia en cambio
D30: Financieros
D31: Pérdidas por aplicación del método de participación patrimonial
D32: Gastos diversos
D33: Donaciones
D34: Total otros gastos | E34: =SUM(E28:E33) | F34: =SUM(F28:F33) | G34: =SUM(G28:G33) | H34: =SUM(H28:H33) | I34: =SUM(I28:I33) | J34: =SUM(J28:J33) | K34: =SUM(K28:K33) | L34: =SUM(L28:L33) | M34: =SUM(M28:M33)
C35: Impuesto a las ganancias corrientes
C36: Impuesto a las ganancias diferido
C37: Bienes y servicios públicos para la venta [resumen]
D38: Compras en bloque y/o a largo plazo
D39: Compras en bolsa y/o a corto plazo
D40: Gastos por suministro de agua potable (agua en bloque)
D41: Gastos de conexión
D42: Uso de Líneas, redes y ductos
...

Sheet Hoja23
B2: Indice
B3: Archivo: | C3: I:\Proyectos2025\proyecto_niif\_backup_legacy\R414\R414Ind_ID20037_2024-12-31.xbrl
B4: Empresa: | C4: 20037
B5: Vista: | C5: [900019] FC02 - Complementario ingresos
B6: Eje X: | C6: N/A
B7: Eje Y: | C7: N/A
B8: Eje Z: | C8: Periodo Actual
I10: Ingresos, devoluciones, rebajas y descuentos [miembro]
I11: Ingresos brutos [miembro] | J11: Devoluciones, rebajas y descuentos [miembro] | K11: Ingresos netos [miembro]
B12: Información a revelar sobre ingresos y devoluciones [resumen]
C13: Información a revelar sobre ingresos [resumen]
D14: Acueducto [resumen]
E15: Abastecimiento
E16: Distribución
E17: Comercialización
E18: Subtotal Ingresos Acueducto | I18: =SUM(I15:I17)
D19: Alcantarillado [resumen]
E20: Recolección y transporte
E21: Tratamiento de aguas residuales
E22: Comercialización
E23: Subtotal Ingresos Alcantarillado | I23: =SUM(I20:I22)
D24: Aseo [resumen]
E25: Recolección y transporte de residuos no aprovechables
E26: Disposición final
E27: Tratamiento de lixiviados
E28: Comercialización
E29: Corte de césped
E30: Poda de arboles
E31: Limpieza y lavado de áreas públicas
E32: Limpieza de playa costeras y rivereñas
E33: Suministro e Instalación de cestas en vías y áreas públicas
E34: Mantenimiento de cestas en vías y áreas públicas
E35: Barrido y Limpieza
E36: Transferencia
... E39: Otros ingresos servicio aseo
E40: Subtotal Ingresos Aseo | I40: =SUM(I25:I39)
D41: Energía Eléctrica [resumen]
E42: ENERGIA - SIN [resumen]
F43: Generación [resumen]
G44: Ventas de contratos bilaterales
...

Sheet Hoja24
B2: Indice
B3: Archivo: | C3: I:\Proyectos2025\proyecto_niif\_backup_legacy\R414\R414Ind_ID20037_2024-12-31.xbrl
B4: Empresa: | C4: 20037
B5: Vista: | C5: [900021] FC03-1 - CXC - Acueducto (Detallado por estrato)
B6: Eje X: | C6: N/A
B7: Eje Y: | C7: N/A
B8: Eje Z: | C8: Periodo Actual
G10: Formato Complementario - Cuentas por cobrar (Acueducto - Detallado por estrato)
G11: Corriente / No corriente [miembro] | J11: Total [miembro]
G12: Corriente [miembro] | H12: No Corriente [miembro] | J12: No vencida [miembro] | K12: Vencida 1 a 30 días [miembro] | L12: Vencida 31 a 60 días [miembro] | M12: Vencida 61 a 90 días [miembro] | N12: Vencida 91 a 120 días [miembro] | O12: Vencida 121 a 150 días [miembro] | P12: Vencida 151 a 180 días [miembro] | Q12: Vencida 181 a 360 días [miembro] | R12: Vencida mayor de 360 días [miembro]
B13: Formato Complementario - Cuentas por cobrar (Acueducto - Detallado por estrato) [partidas]
C14: Detalle Cuentas por cobrar Servicio de Acueducto
D15: Servicio de acueducto [partidas]
E16: Distribución
E17: Otros Servicios
E18: Comercialización [resumen]
F19: Residencial Estrato 1
F20: Residencial Estrato 2
F21: Residencial Estrato 3
F22: Residencial Estrato 4
F23: Residencial Estrato 5
F24: Residencial Estrato 6
F25: No residencial industrial
F26: No residencial comercial
F27: No residencial oficial
F28: No residencial especial
F29: Total Comercialización | G29: =SUM(G19:G28) | H29: =SUM(H19:H28) | I29: =SUM(I19:I28) | J29: =SUM(J19:J28) | K29: =SUM(K19:K28) | L29: =SUM(L19:L28) | M29: =SUM(M19:M28) | N29: =SUM(N19:N28) | ... S29: =SUM(S19:S28)
E30: Cuentas por Cobrar brutas servicio de Acueducto | G30: =G16+G17+G29 | H30: =H16+H17+H29 | I30: =I16+I17+I29 | J30: =J16+J17+J29 | K30: =K16+K17+K29 | L30: =L16+L17+L29 | M30: =M16+M17+M29 | N30: =N16+N17+N29 | ... S30: =S16+S17+S29
C31: Detalle Deterioro cuentas por cobrar Servicio de Acueducto
D32: Deterioro de cuentas por cobrar [partidas]
E33: Distribución
E34: Otros Servicios
E35: Comercialización [resumen]
F36: Residencial Estrato 1
F37: Residencial Estrato 2
F38: Residencial Estrato 3
F39: Residencial Estrato 4
F40: Residencial Estrato 5
F41: Residencial Estrato 6
F42: No Residencial Industrial
...

Sheet Hoja25
B2: Indice
B3: Archivo: | C3: I:\Proyectos2025\proyecto_niif\_backup_legacy\R414\R414Ind_ID20037_2024-12-31.xbrl
B4: Empresa: | C4: 20037
B5: Vista: | C5: [900022] FC03-2 - CXC - Alcantarillado (Detallado por estrato)
B6: Eje X: | C6: N/A
B7: Eje Y: | C7: N/A
B8: Eje Z: | C8: Periodo Actual
G10: Formato Complementario - Cuentas por cobrar (Alcantarillado - Detallado por estrato)
G11: Corriente / No corriente [miembro] | J11: Total [miembro]
G12: Corriente [miembro] | H12: No Corriente [miembro] | J12: No vencida [miembro] | K12: Vencida 1 a 30 días [miembro] | L12: Vencida 31 a 60 días [miembro] | M12: Vencida 61 a 90 días [miembro] | N12: Vencida 91 a 120 días [miembro] | O12: Vencida 121 a 150 días [miembro] | P12: Vencida 151 a 180 días [miembro] | Q12: Vencida 181 a 360 días [miembro] | R12: Vencida mayor de 360 días [miembro]
B13: Formato Complementario - Cuentas por cobrar (Alcantarillado - Detallado por estrato) [partidas]
C14: Detalle Cuentas por cobrar Servicio de Alcantarillado
D15: Servicio de alcantarillado [resumen]
E16: Recolección
E17: Tratamiento y disposición final
E18: Comercialización [resumen]
F19: Residencial Estrato 1
F20: Residencial Estrato 2
F21: Residencial Estrato 3
F22: Residencial Estrato 4
F23: Residencial Estrato 5
F24: Residencial Estrato 6
F25: No residencial industrial
F26: No residencial comercial
F27: No residencial oficial
F28: No residencial especial
F29: Total Comercialización | G29: =SUM(G19:G28) | H29: =SUM(H19:H28) | I29: =SUM(I19:I28) | J29: =SUM(J19:J28) | K29: =SUM(K19:K28) | L29: =SUM(L19:L28) | M29: =SUM(M19:M28) | N29: =SUM(N19:N28) | ... S29: =SUM(S19:S28)
E30: Cuentas por Cobrar brutas servicio de Alcantarillado | G30: =G16+G17+G29 | H30: =H16+H17+H29 | I30: =I16+I17+I29 | J30: =J16+J17+J29 | K30: =K16+K17+K29 | L30: =L16+L17+L29 | M30: =M16+M17+M29 | N30: =N16+N17+N29 | ... S30: =S16+S17+S29
C31: Detalle Deterioro cuentas por cobrar Servicio de Alcantarillado
D32: Deterioro de cuentas por cobrar [partidas]
E33: Recolección
E34: Tratamiento y disposición final
E35: Comercialización [resumen]
F36: Residencial Estrato 1
F37: Residencial Estrato 2
F38: Residencial Estrato 3
F39: Residencial Estrato 4
F40: Residencial Estrato 5
F41: Residencial Estrato 6
F42: No Residencial Industrial
...

Sheet Hoja26
B2: Indice
B3: Archivo: | C3: I:\Proyectos2025\proyecto_niif\_backup_legacy\R414\R414Ind_ID20037_2024-12-31.xbrl
B4: Empresa: | C4: 20037
B5: Vista: | C5: [900023] FC03-3 - CXC - Aseo (Detallado por estrato)
B6: Eje X: | C6: N/A
B7: Eje Y: | C7: N/A
B8: Eje Z: | C8: Periodo Actual
E10: Formato Complementario - Cuentas por cobrar (Aseo - Detallado por estrato)
E11: Corriente / No corriente [miembro] | H11: Total [miembro]
E12: Corriente [miembro] | F12: No Corriente [miembro] | H12: No vencida [miembro] | I12: Vencida 1 a 30 días [miembro] | J12: Vencida 31 a 60 días [miembro] | K12: Vencida 61 a 90 días [miembro] | L12: Vencida 91 a 120 días [miembro] | M12: Vencida 121 a 150 días [miembro] | N12: Vencida 151 a 180 días [miembro] | O12: Vencida 181 a 360 días [miembro] | P12: Vencida mayor de 360 días [miembro]
B13: Formato Complementario - Cuentas por cobrar (Aseo - Detallado por estrato) [partidas]
C14: Detalle Cuentas por cobrar Servicio de Aseo
D15: Residencial Estrato 1
D16: Residencial Estrato 2
D17: Residencial Estrato 3
D18: Residencial Estrato 4
D19: Residencial Estrato 5
D20: Residencial Estrato 6
D21: No residencial industrial
D22: No residencial comercial
D23: No residencial oficial
D24: No residencial especial
D25: Cuentas por Cobrar brutas servicio de Aseo | E25: =SUM(E15:E24) | F25: =SUM(F15:F24) | G25: =SUM(G15:G24) | H25: =SUM(H15:H24) | I25: =SUM(I15:I24) | J25: =SUM(J15:J24) | K25: =SUM(K15:K24) | L25: =SUM(L15:L24) | ... Q25: =SUM(Q15:Q24)
C26: Detalle Deterioro cuentas por cobrar Servicio de Aseo
D27: Residencial Estrato 1
D28: Residencial Estrato 2
D29: Residencial Estrato 3
D30: Residencial Estrato 4
